2019-05-20 13:39:15,586 [Dummy-1:7264] [C:\Users\Administrator.SC-201903241453\AppData\Local\Programs\Python\Python36-32\lib\site-packages\django\db\backends\utils.py:execute:111] [DEBUG]- (0.000) SELECT @@SQL_AUTO_IS_NULL; args=None
2019-05-20 13:39:15,586 [Dummy-1:7264] [C:\Users\Administrator.SC-201903241453\AppData\Local\Programs\Python\Python36-32\lib\site-packages\django\db\backends\utils.py:execute:111] [DEBUG]- (0.000) SET SESSION TRANSACTION ISOLATION LEVEL READ COMMITTED; args=None
2019-05-20 13:39:15,596 [Dummy-1:7264] [C:\Users\Administrator.SC-201903241453\AppData\Local\Programs\Python\Python36-32\lib\site-packages\django\db\backends\utils.py:execute:111] [DEBUG]- (0.010) SELECT VERSION(); args=None
2019-05-20 13:39:16,660 [Dummy-1:7264] [C:\Users\Administrator.SC-201903241453\AppData\Local\Programs\Python\Python36-32\lib\site-packages\django\db\backends\utils.py:execute:111] [DEBUG]- (0.000) SET SESSION TRANSACTION ISOLATION LEVEL READ COMMITTED; args=None
2019-05-20 13:39:16,680 [Dummy-1:7264] [C:\Users\Administrator.SC-201903241453\AppData\Local\Programs\Python\Python36-32\lib\site-packages\django\db\backends\utils.py:execute:111] [DEBUG]- (0.020) SHOW FULL TABLES; args=None
2019-05-20 13:39:16,690 [Dummy-1:7264] [C:\Users\Administrator.SC-201903241453\AppData\Local\Programs\Python\Python36-32\lib\site-packages\django\db\backends\utils.py:execute:111] [DEBUG]- (0.000) SELECT `django_migrations`.`app`, `django_migrations`.`name` FROM `django_migrations`; args=()
2019-05-20 13:39:36,584 [Thread-2:7324] [C:\Users\Administrator.SC-201903241453\AppData\Local\Programs\Python\Python36-32\lib\site-packages\django\template\base.py:_resolve_lookup:878] [DEBUG]- Exception while resolving variable 'name' in template 'unknown'.
Traceback (most recent call last):
  File "C:\Users\Administrator.SC-201903241453\AppData\Local\Programs\Python\Python36-32\lib\site-packages\django\core\handlers\exception.py", line 35, in inner
    response = get_response(request)
  File "C:\Users\Administrator.SC-201903241453\AppData\Local\Programs\Python\Python36-32\lib\site-packages\django\core\handlers\base.py", line 113, in _get_response
    resolver_match = resolver.resolve(request.path_info)
  File "C:\Users\Administrator.SC-201903241453\AppData\Local\Programs\Python\Python36-32\lib\site-packages\django\urls\resolvers.py", line 523, in resolve
    raise Resolver404({'tried': tried, 'path': new_path})
django.urls.exceptions.Resolver404: {'tried': [[<URLResolver <URLPattern list> (admin:admin) 'admin/'>], [<URLResolver <module 'backend.version_1_0' from 'D:\\360MoveData\\Users\\Administrator.SC-201903241453\\Desktop\\backend-7-3\\backend\\version_1_0.py'> (None:None) 'api/v1.0/'>]], 'path': 'favicon.ico'}

During handling of the above exception, another exception occurred:

Traceback (most recent call last):
  File "C:\Users\Administrator.SC-201903241453\AppData\Local\Programs\Python\Python36-32\lib\site-packages\django\template\base.py", line 835, in _resolve_lookup
    current = current[bit]
TypeError: 'URLResolver' object is not subscriptable

During handling of the above exception, another exception occurred:

Traceback (most recent call last):
  File "C:\Users\Administrator.SC-201903241453\AppData\Local\Programs\Python\Python36-32\lib\site-packages\django\template\base.py", line 843, in _resolve_lookup
    current = getattr(current, bit)
AttributeError: 'URLResolver' object has no attribute 'name'

During handling of the above exception, another exception occurred:

Traceback (most recent call last):
  File "C:\Users\Administrator.SC-201903241453\AppData\Local\Programs\Python\Python36-32\lib\site-packages\django\template\base.py", line 849, in _resolve_lookup
    current = current[int(bit)]
ValueError: invalid literal for int() with base 10: 'name'

During handling of the above exception, another exception occurred:

Traceback (most recent call last):
  File "C:\Users\Administrator.SC-201903241453\AppData\Local\Programs\Python\Python36-32\lib\site-packages\django\template\base.py", line 856, in _resolve_lookup
    (bit, current))  # missing attribute
django.template.base.VariableDoesNotExist: Failed lookup for key [name] in <URLResolver <URLPattern list> (admin:admin) 'admin/'>
2019-05-20 13:39:36,599 [Thread-2:7324] [C:\Users\Administrator.SC-201903241453\AppData\Local\Programs\Python\Python36-32\lib\site-packages\django\template\base.py:_resolve_lookup:878] [DEBUG]- Exception while resolving variable 'name' in template 'unknown'.
Traceback (most recent call last):
  File "C:\Users\Administrator.SC-201903241453\AppData\Local\Programs\Python\Python36-32\lib\site-packages\django\core\handlers\exception.py", line 35, in inner
    response = get_response(request)
  File "C:\Users\Administrator.SC-201903241453\AppData\Local\Programs\Python\Python36-32\lib\site-packages\django\core\handlers\base.py", line 113, in _get_response
    resolver_match = resolver.resolve(request.path_info)
  File "C:\Users\Administrator.SC-201903241453\AppData\Local\Programs\Python\Python36-32\lib\site-packages\django\urls\resolvers.py", line 523, in resolve
    raise Resolver404({'tried': tried, 'path': new_path})
django.urls.exceptions.Resolver404: {'tried': [[<URLResolver <URLPattern list> (admin:admin) 'admin/'>], [<URLResolver <module 'backend.version_1_0' from 'D:\\360MoveData\\Users\\Administrator.SC-201903241453\\Desktop\\backend-7-3\\backend\\version_1_0.py'> (None:None) 'api/v1.0/'>]], 'path': 'favicon.ico'}

During handling of the above exception, another exception occurred:

Traceback (most recent call last):
  File "C:\Users\Administrator.SC-201903241453\AppData\Local\Programs\Python\Python36-32\lib\site-packages\django\template\base.py", line 835, in _resolve_lookup
    current = current[bit]
TypeError: 'URLResolver' object is not subscriptable

During handling of the above exception, another exception occurred:

Traceback (most recent call last):
  File "C:\Users\Administrator.SC-201903241453\AppData\Local\Programs\Python\Python36-32\lib\site-packages\django\template\base.py", line 843, in _resolve_lookup
    current = getattr(current, bit)
AttributeError: 'URLResolver' object has no attribute 'name'

During handling of the above exception, another exception occurred:

Traceback (most recent call last):
  File "C:\Users\Administrator.SC-201903241453\AppData\Local\Programs\Python\Python36-32\lib\site-packages\django\template\base.py", line 849, in _resolve_lookup
    current = current[int(bit)]
ValueError: invalid literal for int() with base 10: 'name'

During handling of the above exception, another exception occurred:

Traceback (most recent call last):
  File "C:\Users\Administrator.SC-201903241453\AppData\Local\Programs\Python\Python36-32\lib\site-packages\django\template\base.py", line 856, in _resolve_lookup
    (bit, current))  # missing attribute
django.template.base.VariableDoesNotExist: Failed lookup for key [name] in <URLResolver <module 'backend.version_1_0' from 'D:\\360MoveData\\Users\\Administrator.SC-201903241453\\Desktop\\backend-7-3\\backend\\version_1_0.py'> (None:None) 'api/v1.0/'>
2019-05-20 13:39:36,607 [Thread-2:7324] [C:\Users\Administrator.SC-201903241453\AppData\Local\Programs\Python\Python36-32\lib\site-packages\django\core\handlers\base.py:get_response:93] [WARNING]- Not Found: /favicon.ico
2019-05-20 13:39:36,610 [Thread-2:7324] [C:\Users\Administrator.SC-201903241453\AppData\Local\Programs\Python\Python36-32\lib\site-packages\django\core\servers\basehttp.py:log_message:124] [WARNING]- "GET /favicon.ico HTTP/1.1" 404 2082
2019-05-20 13:39:52,853 [Thread-3:7668] [C:\Users\Administrator.SC-201903241453\AppData\Local\Programs\Python\Python36-32\lib\site-packages\django\template\base.py:_resolve_lookup:878] [DEBUG]- Exception while resolving variable 'name' in template 'unknown'.
Traceback (most recent call last):
  File "C:\Users\Administrator.SC-201903241453\AppData\Local\Programs\Python\Python36-32\lib\site-packages\django\core\handlers\exception.py", line 35, in inner
    response = get_response(request)
  File "C:\Users\Administrator.SC-201903241453\AppData\Local\Programs\Python\Python36-32\lib\site-packages\django\core\handlers\base.py", line 113, in _get_response
    resolver_match = resolver.resolve(request.path_info)
  File "C:\Users\Administrator.SC-201903241453\AppData\Local\Programs\Python\Python36-32\lib\site-packages\django\urls\resolvers.py", line 523, in resolve
    raise Resolver404({'tried': tried, 'path': new_path})
django.urls.exceptions.Resolver404: {'tried': [[<URLResolver <URLPattern list> (admin:admin) 'admin/'>], [<URLResolver <module 'backend.version_1_0' from 'D:\\360MoveData\\Users\\Administrator.SC-201903241453\\Desktop\\backend-7-3\\backend\\version_1_0.py'> (None:None) 'api/v1.0/'>]], 'path': 'favicon.ico'}

During handling of the above exception, another exception occurred:

Traceback (most recent call last):
  File "C:\Users\Administrator.SC-201903241453\AppData\Local\Programs\Python\Python36-32\lib\site-packages\django\template\base.py", line 835, in _resolve_lookup
    current = current[bit]
TypeError: 'URLResolver' object is not subscriptable

During handling of the above exception, another exception occurred:

Traceback (most recent call last):
  File "C:\Users\Administrator.SC-201903241453\AppData\Local\Programs\Python\Python36-32\lib\site-packages\django\template\base.py", line 843, in _resolve_lookup
    current = getattr(current, bit)
AttributeError: 'URLResolver' object has no attribute 'name'

During handling of the above exception, another exception occurred:

Traceback (most recent call last):
  File "C:\Users\Administrator.SC-201903241453\AppData\Local\Programs\Python\Python36-32\lib\site-packages\django\template\base.py", line 849, in _resolve_lookup
    current = current[int(bit)]
ValueError: invalid literal for int() with base 10: 'name'

During handling of the above exception, another exception occurred:

Traceback (most recent call last):
  File "C:\Users\Administrator.SC-201903241453\AppData\Local\Programs\Python\Python36-32\lib\site-packages\django\template\base.py", line 856, in _resolve_lookup
    (bit, current))  # missing attribute
django.template.base.VariableDoesNotExist: Failed lookup for key [name] in <URLResolver <URLPattern list> (admin:admin) 'admin/'>
2019-05-20 13:39:52,857 [Thread-3:7668] [C:\Users\Administrator.SC-201903241453\AppData\Local\Programs\Python\Python36-32\lib\site-packages\django\template\base.py:_resolve_lookup:878] [DEBUG]- Exception while resolving variable 'name' in template 'unknown'.
Traceback (most recent call last):
  File "C:\Users\Administrator.SC-201903241453\AppData\Local\Programs\Python\Python36-32\lib\site-packages\django\core\handlers\exception.py", line 35, in inner
    response = get_response(request)
  File "C:\Users\Administrator.SC-201903241453\AppData\Local\Programs\Python\Python36-32\lib\site-packages\django\core\handlers\base.py", line 113, in _get_response
    resolver_match = resolver.resolve(request.path_info)
  File "C:\Users\Administrator.SC-201903241453\AppData\Local\Programs\Python\Python36-32\lib\site-packages\django\urls\resolvers.py", line 523, in resolve
    raise Resolver404({'tried': tried, 'path': new_path})
django.urls.exceptions.Resolver404: {'tried': [[<URLResolver <URLPattern list> (admin:admin) 'admin/'>], [<URLResolver <module 'backend.version_1_0' from 'D:\\360MoveData\\Users\\Administrator.SC-201903241453\\Desktop\\backend-7-3\\backend\\version_1_0.py'> (None:None) 'api/v1.0/'>]], 'path': 'favicon.ico'}

During handling of the above exception, another exception occurred:

Traceback (most recent call last):
  File "C:\Users\Administrator.SC-201903241453\AppData\Local\Programs\Python\Python36-32\lib\site-packages\django\template\base.py", line 835, in _resolve_lookup
    current = current[bit]
TypeError: 'URLResolver' object is not subscriptable

During handling of the above exception, another exception occurred:

Traceback (most recent call last):
  File "C:\Users\Administrator.SC-201903241453\AppData\Local\Programs\Python\Python36-32\lib\site-packages\django\template\base.py", line 843, in _resolve_lookup
    current = getattr(current, bit)
AttributeError: 'URLResolver' object has no attribute 'name'

During handling of the above exception, another exception occurred:

Traceback (most recent call last):
  File "C:\Users\Administrator.SC-201903241453\AppData\Local\Programs\Python\Python36-32\lib\site-packages\django\template\base.py", line 849, in _resolve_lookup
    current = current[int(bit)]
ValueError: invalid literal for int() with base 10: 'name'

During handling of the above exception, another exception occurred:

Traceback (most recent call last):
  File "C:\Users\Administrator.SC-201903241453\AppData\Local\Programs\Python\Python36-32\lib\site-packages\django\template\base.py", line 856, in _resolve_lookup
    (bit, current))  # missing attribute
django.template.base.VariableDoesNotExist: Failed lookup for key [name] in <URLResolver <module 'backend.version_1_0' from 'D:\\360MoveData\\Users\\Administrator.SC-201903241453\\Desktop\\backend-7-3\\backend\\version_1_0.py'> (None:None) 'api/v1.0/'>
2019-05-20 13:39:52,866 [Thread-3:7668] [C:\Users\Administrator.SC-201903241453\AppData\Local\Programs\Python\Python36-32\lib\site-packages\django\core\handlers\base.py:get_response:93] [WARNING]- Not Found: /favicon.ico
2019-05-20 13:39:52,869 [Thread-3:7668] [C:\Users\Administrator.SC-201903241453\AppData\Local\Programs\Python\Python36-32\lib\site-packages\django\core\servers\basehttp.py:log_message:124] [WARNING]- "GET /favicon.ico HTTP/1.1" 404 2082
2019-05-20 13:39:59,431 [Thread-4:7856] [C:\Users\Administrator.SC-201903241453\AppData\Local\Programs\Python\Python36-32\lib\site-packages\django\db\backends\utils.py:execute:111] [DEBUG]- (0.000) SELECT @@SQL_AUTO_IS_NULL; args=None
2019-05-20 13:39:59,433 [Thread-4:7856] [C:\Users\Administrator.SC-201903241453\AppData\Local\Programs\Python\Python36-32\lib\site-packages\django\db\backends\utils.py:execute:111] [DEBUG]- (0.000) SET SESSION TRANSACTION ISOLATION LEVEL READ COMMITTED; args=None
2019-05-20 13:39:59,434 [Thread-4:7856] [C:\Users\Administrator.SC-201903241453\AppData\Local\Programs\Python\Python36-32\lib\site-packages\django\db\backends\utils.py:execute:111] [DEBUG]- (0.001) SELECT VERSION(); args=None
2019-05-20 13:39:59,439 [Thread-4:7856] [C:\Users\Administrator.SC-201903241453\AppData\Local\Programs\Python\Python36-32\lib\site-packages\django\db\backends\utils.py:execute:111] [DEBUG]- (0.000) SET SESSION TRANSACTION ISOLATION LEVEL READ COMMITTED; args=None
2019-05-20 13:39:59,443 [Thread-4:7856] [C:\Users\Administrator.SC-201903241453\AppData\Local\Programs\Python\Python36-32\lib\site-packages\django\db\backends\utils.py:execute:111] [DEBUG]- (0.003) SELECT `django_session`.`session_key`, `django_session`.`session_data`, `django_session`.`expire_date` FROM `django_session` WHERE (`django_session`.`session_key` = '7m9ujkc2e2in3a9sedd9fv82zwrnzj0z' AND `django_session`.`expire_date` > '2019-05-20 05:39:59'); args=('7m9ujkc2e2in3a9sedd9fv82zwrnzj0z', '2019-05-20 05:39:59')
2019-05-20 13:39:59,448 [Thread-4:7856] [C:\Users\Administrator.SC-201903241453\AppData\Local\Programs\Python\Python36-32\lib\site-packages\django\core\servers\basehttp.py:log_message:124] [INFO]- "GET /api/v1.0/service/weather HTTP/1.1" 200 48
2019-05-20 13:39:59,702 [Thread-5:7860] [C:\Users\Administrator.SC-201903241453\AppData\Local\Programs\Python\Python36-32\lib\site-packages\django\template\base.py:_resolve_lookup:878] [DEBUG]- Exception while resolving variable 'name' in template 'unknown'.
Traceback (most recent call last):
  File "C:\Users\Administrator.SC-201903241453\AppData\Local\Programs\Python\Python36-32\lib\site-packages\django\core\handlers\exception.py", line 35, in inner
    response = get_response(request)
  File "C:\Users\Administrator.SC-201903241453\AppData\Local\Programs\Python\Python36-32\lib\site-packages\django\core\handlers\base.py", line 113, in _get_response
    resolver_match = resolver.resolve(request.path_info)
  File "C:\Users\Administrator.SC-201903241453\AppData\Local\Programs\Python\Python36-32\lib\site-packages\django\urls\resolvers.py", line 523, in resolve
    raise Resolver404({'tried': tried, 'path': new_path})
django.urls.exceptions.Resolver404: {'tried': [[<URLResolver <URLPattern list> (admin:admin) 'admin/'>], [<URLResolver <module 'backend.version_1_0' from 'D:\\360MoveData\\Users\\Administrator.SC-201903241453\\Desktop\\backend-7-3\\backend\\version_1_0.py'> (None:None) 'api/v1.0/'>]], 'path': 'favicon.ico'}

During handling of the above exception, another exception occurred:

Traceback (most recent call last):
  File "C:\Users\Administrator.SC-201903241453\AppData\Local\Programs\Python\Python36-32\lib\site-packages\django\template\base.py", line 835, in _resolve_lookup
    current = current[bit]
TypeError: 'URLResolver' object is not subscriptable

During handling of the above exception, another exception occurred:

Traceback (most recent call last):
  File "C:\Users\Administrator.SC-201903241453\AppData\Local\Programs\Python\Python36-32\lib\site-packages\django\template\base.py", line 843, in _resolve_lookup
    current = getattr(current, bit)
AttributeError: 'URLResolver' object has no attribute 'name'

During handling of the above exception, another exception occurred:

Traceback (most recent call last):
  File "C:\Users\Administrator.SC-201903241453\AppData\Local\Programs\Python\Python36-32\lib\site-packages\django\template\base.py", line 849, in _resolve_lookup
    current = current[int(bit)]
ValueError: invalid literal for int() with base 10: 'name'

During handling of the above exception, another exception occurred:

Traceback (most recent call last):
  File "C:\Users\Administrator.SC-201903241453\AppData\Local\Programs\Python\Python36-32\lib\site-packages\django\template\base.py", line 856, in _resolve_lookup
    (bit, current))  # missing attribute
django.template.base.VariableDoesNotExist: Failed lookup for key [name] in <URLResolver <URLPattern list> (admin:admin) 'admin/'>
2019-05-20 13:39:59,713 [Thread-5:7860] [C:\Users\Administrator.SC-201903241453\AppData\Local\Programs\Python\Python36-32\lib\site-packages\django\template\base.py:_resolve_lookup:878] [DEBUG]- Exception while resolving variable 'name' in template 'unknown'.
Traceback (most recent call last):
  File "C:\Users\Administrator.SC-201903241453\AppData\Local\Programs\Python\Python36-32\lib\site-packages\django\core\handlers\exception.py", line 35, in inner
    response = get_response(request)
  File "C:\Users\Administrator.SC-201903241453\AppData\Local\Programs\Python\Python36-32\lib\site-packages\django\core\handlers\base.py", line 113, in _get_response
    resolver_match = resolver.resolve(request.path_info)
  File "C:\Users\Administrator.SC-201903241453\AppData\Local\Programs\Python\Python36-32\lib\site-packages\django\urls\resolvers.py", line 523, in resolve
    raise Resolver404({'tried': tried, 'path': new_path})
django.urls.exceptions.Resolver404: {'tried': [[<URLResolver <URLPattern list> (admin:admin) 'admin/'>], [<URLResolver <module 'backend.version_1_0' from 'D:\\360MoveData\\Users\\Administrator.SC-201903241453\\Desktop\\backend-7-3\\backend\\version_1_0.py'> (None:None) 'api/v1.0/'>]], 'path': 'favicon.ico'}

During handling of the above exception, another exception occurred:

Traceback (most recent call last):
  File "C:\Users\Administrator.SC-201903241453\AppData\Local\Programs\Python\Python36-32\lib\site-packages\django\template\base.py", line 835, in _resolve_lookup
    current = current[bit]
TypeError: 'URLResolver' object is not subscriptable

During handling of the above exception, another exception occurred:

Traceback (most recent call last):
  File "C:\Users\Administrator.SC-201903241453\AppData\Local\Programs\Python\Python36-32\lib\site-packages\django\template\base.py", line 843, in _resolve_lookup
    current = getattr(current, bit)
AttributeError: 'URLResolver' object has no attribute 'name'

During handling of the above exception, another exception occurred:

Traceback (most recent call last):
  File "C:\Users\Administrator.SC-201903241453\AppData\Local\Programs\Python\Python36-32\lib\site-packages\django\template\base.py", line 849, in _resolve_lookup
    current = current[int(bit)]
ValueError: invalid literal for int() with base 10: 'name'

During handling of the above exception, another exception occurred:

Traceback (most recent call last):
  File "C:\Users\Administrator.SC-201903241453\AppData\Local\Programs\Python\Python36-32\lib\site-packages\django\template\base.py", line 856, in _resolve_lookup
    (bit, current))  # missing attribute
django.template.base.VariableDoesNotExist: Failed lookup for key [name] in <URLResolver <module 'backend.version_1_0' from 'D:\\360MoveData\\Users\\Administrator.SC-201903241453\\Desktop\\backend-7-3\\backend\\version_1_0.py'> (None:None) 'api/v1.0/'>
2019-05-20 13:39:59,733 [Thread-5:7860] [C:\Users\Administrator.SC-201903241453\AppData\Local\Programs\Python\Python36-32\lib\site-packages\django\core\handlers\base.py:get_response:93] [WARNING]- Not Found: /favicon.ico
2019-05-20 13:39:59,733 [Thread-5:7860] [C:\Users\Administrator.SC-201903241453\AppData\Local\Programs\Python\Python36-32\lib\site-packages\django\core\servers\basehttp.py:log_message:124] [WARNING]- "GET /favicon.ico HTTP/1.1" 404 2082
2019-05-20 13:40:25,990 [Thread-10:8116] [C:\Users\Administrator.SC-201903241453\AppData\Local\Programs\Python\Python36-32\lib\site-packages\django\template\base.py:_resolve_lookup:878] [DEBUG]- Exception while resolving variable 'name' in template 'unknown'.
Traceback (most recent call last):
  File "C:\Users\Administrator.SC-201903241453\AppData\Local\Programs\Python\Python36-32\lib\site-packages\django\core\handlers\exception.py", line 35, in inner
    response = get_response(request)
  File "C:\Users\Administrator.SC-201903241453\AppData\Local\Programs\Python\Python36-32\lib\site-packages\django\core\handlers\base.py", line 113, in _get_response
    resolver_match = resolver.resolve(request.path_info)
  File "C:\Users\Administrator.SC-201903241453\AppData\Local\Programs\Python\Python36-32\lib\site-packages\django\urls\resolvers.py", line 523, in resolve
    raise Resolver404({'tried': tried, 'path': new_path})
django.urls.exceptions.Resolver404: {'tried': [[<URLResolver <URLPattern list> (admin:admin) 'admin/'>], [<URLResolver <module 'backend.version_1_0' from 'D:\\360MoveData\\Users\\Administrator.SC-201903241453\\Desktop\\backend-7-3\\backend\\version_1_0.py'> (None:None) 'api/v1.0/'>, <URLResolver <module 'apis.urls' from 'D:\\360MoveData\\Users\\Administrator.SC-201903241453\\Desktop\\backend-7-3\\apis\\urls.py'> (None:None) 'service/'>, <URLPattern 'weather'>], [<URLResolver <module 'backend.version_1_0' from 'D:\\360MoveData\\Users\\Administrator.SC-201903241453\\Desktop\\backend-7-3\\backend\\version_1_0.py'> (None:None) 'api/v1.0/'>, <URLResolver <module 'apis.urls' from 'D:\\360MoveData\\Users\\Administrator.SC-201903241453\\Desktop\\backend-7-3\\apis\\urls.py'> (None:None) 'service/'>, <URLPattern 'menu/user'>], [<URLResolver <module 'backend.version_1_0' from 'D:\\360MoveData\\Users\\Administrator.SC-201903241453\\Desktop\\backend-7-3\\backend\\version_1_0.py'> (None:None) 'api/v1.0/'>, <URLResolver <module 'apis.urls' from 'D:\\360MoveData\\Users\\Administrator.SC-201903241453\\Desktop\\backend-7-3\\apis\\urls.py'> (None:None) 'service/'>, <URLPattern 'menu/list'>], [<URLResolver <module 'backend.version_1_0' from 'D:\\360MoveData\\Users\\Administrator.SC-201903241453\\Desktop\\backend-7-3\\backend\\version_1_0.py'> (None:None) 'api/v1.0/'>, <URLResolver <module 'apis.urls' from 'D:\\360MoveData\\Users\\Administrator.SC-201903241453\\Desktop\\backend-7-3\\apis\\urls.py'> (None:None) 'service/'>, <URLPattern 'image'>], [<URLResolver <module 'backend.version_1_0' from 'D:\\360MoveData\\Users\\Administrator.SC-201903241453\\Desktop\\backend-7-3\\backend\\version_1_0.py'> (None:None) 'api/v1.0/'>, <URLResolver <module 'apis.urls' from 'D:\\360MoveData\\Users\\Administrator.SC-201903241453\\Desktop\\backend-7-3\\apis\\urls.py'> (None:None) 'service/'>, <URLPattern 'image/list'>], [<URLResolver <module 'backend.version_1_0' from 'D:\\360MoveData\\Users\\Administrator.SC-201903241453\\Desktop\\backend-7-3\\backend\\version_1_0.py'> (None:None) 'api/v1.0/'>, <URLResolver <module 'apis.urls' from 'D:\\360MoveData\\Users\\Administrator.SC-201903241453\\Desktop\\backend-7-3\\apis\\urls.py'> (None:None) 'service/'>, <URLPattern 'constellation'>], [<URLResolver <module 'backend.version_1_0' from 'D:\\360MoveData\\Users\\Administrator.SC-201903241453\\Desktop\\backend-7-3\\backend\\version_1_0.py'> (None:None) 'api/v1.0/'>, <URLResolver <module 'apis.urls' from 'D:\\360MoveData\\Users\\Administrator.SC-201903241453\\Desktop\\backend-7-3\\apis\\urls.py'> (None:None) 'service/'>, <URLPattern 'joke'>], [<URLResolver <module 'backend.version_1_0' from 'D:\\360MoveData\\Users\\Administrator.SC-201903241453\\Desktop\\backend-7-3\\backend\\version_1_0.py'> (None:None) 'api/v1.0/'>, <URLResolver <module 'apis.urls' from 'D:\\360MoveData\\Users\\Administrator.SC-201903241453\\Desktop\\backend-7-3\\apis\\urls.py'> (None:None) 'service/'>, <URLPattern 'today'>], [<URLResolver <module 'backend.version_1_0' from 'D:\\360MoveData\\Users\\Administrator.SC-201903241453\\Desktop\\backend-7-3\\backend\\version_1_0.py'> (None:None) 'api/v1.0/'>, <URLResolver <module 'apis.urls' from 'D:\\360MoveData\\Users\\Administrator.SC-201903241453\\Desktop\\backend-7-3\\apis\\urls.py'> (None:None) 'service/'>, <URLPattern 'stock'>], [<URLResolver <module 'backend.version_1_0' from 'D:\\360MoveData\\Users\\Administrator.SC-201903241453\\Desktop\\backend-7-3\\backend\\version_1_0.py'> (None:None) 'api/v1.0/'>, <URLResolver <module 'authorization.urls' from 'D:\\360MoveData\\Users\\Administrator.SC-201903241453\\Desktop\\backend-7-3\\authorization\\urls.py'> (None:None) 'auth/'>]], 'path': 'api/v1.0/service/'}

During handling of the above exception, another exception occurred:

Traceback (most recent call last):
  File "C:\Users\Administrator.SC-201903241453\AppData\Local\Programs\Python\Python36-32\lib\site-packages\django\template\base.py", line 835, in _resolve_lookup
    current = current[bit]
TypeError: 'URLResolver' object is not subscriptable

During handling of the above exception, another exception occurred:

Traceback (most recent call last):
  File "C:\Users\Administrator.SC-201903241453\AppData\Local\Programs\Python\Python36-32\lib\site-packages\django\template\base.py", line 843, in _resolve_lookup
    current = getattr(current, bit)
AttributeError: 'URLResolver' object has no attribute 'name'

During handling of the above exception, another exception occurred:

Traceback (most recent call last):
  File "C:\Users\Administrator.SC-201903241453\AppData\Local\Programs\Python\Python36-32\lib\site-packages\django\template\base.py", line 849, in _resolve_lookup
    current = current[int(bit)]
ValueError: invalid literal for int() with base 10: 'name'

During handling of the above exception, another exception occurred:

Traceback (most recent call last):
  File "C:\Users\Administrator.SC-201903241453\AppData\Local\Programs\Python\Python36-32\lib\site-packages\django\template\base.py", line 856, in _resolve_lookup
    (bit, current))  # missing attribute
django.template.base.VariableDoesNotExist: Failed lookup for key [name] in <URLResolver <URLPattern list> (admin:admin) 'admin/'>
2019-05-20 13:40:26,027 [Thread-10:8116] [C:\Users\Administrator.SC-201903241453\AppData\Local\Programs\Python\Python36-32\lib\site-packages\django\template\base.py:_resolve_lookup:878] [DEBUG]- Exception while resolving variable 'name' in template 'unknown'.
Traceback (most recent call last):
  File "C:\Users\Administrator.SC-201903241453\AppData\Local\Programs\Python\Python36-32\lib\site-packages\django\core\handlers\exception.py", line 35, in inner
    response = get_response(request)
  File "C:\Users\Administrator.SC-201903241453\AppData\Local\Programs\Python\Python36-32\lib\site-packages\django\core\handlers\base.py", line 113, in _get_response
    resolver_match = resolver.resolve(request.path_info)
  File "C:\Users\Administrator.SC-201903241453\AppData\Local\Programs\Python\Python36-32\lib\site-packages\django\urls\resolvers.py", line 523, in resolve
    raise Resolver404({'tried': tried, 'path': new_path})
django.urls.exceptions.Resolver404: {'tried': [[<URLResolver <URLPattern list> (admin:admin) 'admin/'>], [<URLResolver <module 'backend.version_1_0' from 'D:\\360MoveData\\Users\\Administrator.SC-201903241453\\Desktop\\backend-7-3\\backend\\version_1_0.py'> (None:None) 'api/v1.0/'>, <URLResolver <module 'apis.urls' from 'D:\\360MoveData\\Users\\Administrator.SC-201903241453\\Desktop\\backend-7-3\\apis\\urls.py'> (None:None) 'service/'>, <URLPattern 'weather'>], [<URLResolver <module 'backend.version_1_0' from 'D:\\360MoveData\\Users\\Administrator.SC-201903241453\\Desktop\\backend-7-3\\backend\\version_1_0.py'> (None:None) 'api/v1.0/'>, <URLResolver <module 'apis.urls' from 'D:\\360MoveData\\Users\\Administrator.SC-201903241453\\Desktop\\backend-7-3\\apis\\urls.py'> (None:None) 'service/'>, <URLPattern 'menu/user'>], [<URLResolver <module 'backend.version_1_0' from 'D:\\360MoveData\\Users\\Administrator.SC-201903241453\\Desktop\\backend-7-3\\backend\\version_1_0.py'> (None:None) 'api/v1.0/'>, <URLResolver <module 'apis.urls' from 'D:\\360MoveData\\Users\\Administrator.SC-201903241453\\Desktop\\backend-7-3\\apis\\urls.py'> (None:None) 'service/'>, <URLPattern 'menu/list'>], [<URLResolver <module 'backend.version_1_0' from 'D:\\360MoveData\\Users\\Administrator.SC-201903241453\\Desktop\\backend-7-3\\backend\\version_1_0.py'> (None:None) 'api/v1.0/'>, <URLResolver <module 'apis.urls' from 'D:\\360MoveData\\Users\\Administrator.SC-201903241453\\Desktop\\backend-7-3\\apis\\urls.py'> (None:None) 'service/'>, <URLPattern 'image'>], [<URLResolver <module 'backend.version_1_0' from 'D:\\360MoveData\\Users\\Administrator.SC-201903241453\\Desktop\\backend-7-3\\backend\\version_1_0.py'> (None:None) 'api/v1.0/'>, <URLResolver <module 'apis.urls' from 'D:\\360MoveData\\Users\\Administrator.SC-201903241453\\Desktop\\backend-7-3\\apis\\urls.py'> (None:None) 'service/'>, <URLPattern 'image/list'>], [<URLResolver <module 'backend.version_1_0' from 'D:\\360MoveData\\Users\\Administrator.SC-201903241453\\Desktop\\backend-7-3\\backend\\version_1_0.py'> (None:None) 'api/v1.0/'>, <URLResolver <module 'apis.urls' from 'D:\\360MoveData\\Users\\Administrator.SC-201903241453\\Desktop\\backend-7-3\\apis\\urls.py'> (None:None) 'service/'>, <URLPattern 'constellation'>], [<URLResolver <module 'backend.version_1_0' from 'D:\\360MoveData\\Users\\Administrator.SC-201903241453\\Desktop\\backend-7-3\\backend\\version_1_0.py'> (None:None) 'api/v1.0/'>, <URLResolver <module 'apis.urls' from 'D:\\360MoveData\\Users\\Administrator.SC-201903241453\\Desktop\\backend-7-3\\apis\\urls.py'> (None:None) 'service/'>, <URLPattern 'joke'>], [<URLResolver <module 'backend.version_1_0' from 'D:\\360MoveData\\Users\\Administrator.SC-201903241453\\Desktop\\backend-7-3\\backend\\version_1_0.py'> (None:None) 'api/v1.0/'>, <URLResolver <module 'apis.urls' from 'D:\\360MoveData\\Users\\Administrator.SC-201903241453\\Desktop\\backend-7-3\\apis\\urls.py'> (None:None) 'service/'>, <URLPattern 'today'>], [<URLResolver <module 'backend.version_1_0' from 'D:\\360MoveData\\Users\\Administrator.SC-201903241453\\Desktop\\backend-7-3\\backend\\version_1_0.py'> (None:None) 'api/v1.0/'>, <URLResolver <module 'apis.urls' from 'D:\\360MoveData\\Users\\Administrator.SC-201903241453\\Desktop\\backend-7-3\\apis\\urls.py'> (None:None) 'service/'>, <URLPattern 'stock'>], [<URLResolver <module 'backend.version_1_0' from 'D:\\360MoveData\\Users\\Administrator.SC-201903241453\\Desktop\\backend-7-3\\backend\\version_1_0.py'> (None:None) 'api/v1.0/'>, <URLResolver <module 'authorization.urls' from 'D:\\360MoveData\\Users\\Administrator.SC-201903241453\\Desktop\\backend-7-3\\authorization\\urls.py'> (None:None) 'auth/'>]], 'path': 'api/v1.0/service/'}

During handling of the above exception, another exception occurred:

Traceback (most recent call last):
  File "C:\Users\Administrator.SC-201903241453\AppData\Local\Programs\Python\Python36-32\lib\site-packages\django\template\base.py", line 835, in _resolve_lookup
    current = current[bit]
TypeError: 'URLResolver' object is not subscriptable

During handling of the above exception, another exception occurred:

Traceback (most recent call last):
  File "C:\Users\Administrator.SC-201903241453\AppData\Local\Programs\Python\Python36-32\lib\site-packages\django\template\base.py", line 843, in _resolve_lookup
    current = getattr(current, bit)
AttributeError: 'URLResolver' object has no attribute 'name'

During handling of the above exception, another exception occurred:

Traceback (most recent call last):
  File "C:\Users\Administrator.SC-201903241453\AppData\Local\Programs\Python\Python36-32\lib\site-packages\django\template\base.py", line 849, in _resolve_lookup
    current = current[int(bit)]
ValueError: invalid literal for int() with base 10: 'name'

During handling of the above exception, another exception occurred:

Traceback (most recent call last):
  File "C:\Users\Administrator.SC-201903241453\AppData\Local\Programs\Python\Python36-32\lib\site-packages\django\template\base.py", line 856, in _resolve_lookup
    (bit, current))  # missing attribute
django.template.base.VariableDoesNotExist: Failed lookup for key [name] in <URLResolver <module 'authorization.urls' from 'D:\\360MoveData\\Users\\Administrator.SC-201903241453\\Desktop\\backend-7-3\\authorization\\urls.py'> (None:None) 'auth/'>
2019-05-20 13:40:26,058 [Thread-10:8116] [C:\Users\Administrator.SC-201903241453\AppData\Local\Programs\Python\Python36-32\lib\site-packages\django\core\handlers\base.py:get_response:93] [WARNING]- Not Found: /api/v1.0/service/
2019-05-20 13:40:26,062 [Thread-10:8116] [C:\Users\Administrator.SC-201903241453\AppData\Local\Programs\Python\Python36-32\lib\site-packages\django\core\servers\basehttp.py:log_message:124] [WARNING]- "GET /api/v1.0/service/ HTTP/1.1" 404 4118
2019-05-20 13:40:39,189 [Thread-16:5808] [C:\Users\Administrator.SC-201903241453\AppData\Local\Programs\Python\Python36-32\lib\site-packages\django\db\backends\utils.py:execute:111] [DEBUG]- (0.001) SELECT @@SQL_AUTO_IS_NULL; args=None
2019-05-20 13:40:39,192 [Thread-16:5808] [C:\Users\Administrator.SC-201903241453\AppData\Local\Programs\Python\Python36-32\lib\site-packages\django\db\backends\utils.py:execute:111] [DEBUG]- (0.001) SET SESSION TRANSACTION ISOLATION LEVEL READ COMMITTED; args=None
2019-05-20 13:40:39,194 [Thread-16:5808] [C:\Users\Administrator.SC-201903241453\AppData\Local\Programs\Python\Python36-32\lib\site-packages\django\db\backends\utils.py:execute:111] [DEBUG]- (0.000) SELECT VERSION(); args=None
2019-05-20 13:40:39,208 [Thread-16:5808] [C:\Users\Administrator.SC-201903241453\AppData\Local\Programs\Python\Python36-32\lib\site-packages\django\db\backends\utils.py:execute:111] [DEBUG]- (0.000) SET SESSION TRANSACTION ISOLATION LEVEL READ COMMITTED; args=None
2019-05-20 13:40:39,213 [Thread-16:5808] [C:\Users\Administrator.SC-201903241453\AppData\Local\Programs\Python\Python36-32\lib\site-packages\django\db\backends\utils.py:execute:111] [DEBUG]- (0.002) SELECT `django_session`.`session_key`, `django_session`.`session_data`, `django_session`.`expire_date` FROM `django_session` WHERE (`django_session`.`session_key` = '7m9ujkc2e2in3a9sedd9fv82zwrnzj0z' AND `django_session`.`expire_date` > '2019-05-20 05:40:39'); args=('7m9ujkc2e2in3a9sedd9fv82zwrnzj0z', '2019-05-20 05:40:39')
2019-05-20 13:40:39,220 [Thread-16:5808] [C:\Users\Administrator.SC-201903241453\AppData\Local\Programs\Python\Python36-32\lib\site-packages\django\core\servers\basehttp.py:log_message:124] [INFO]- "GET /api/v1.0/service/menu/user HTTP/1.1" 200 48
2019-05-20 13:40:45,401 [Thread-22:6420] [C:\Users\Administrator.SC-201903241453\AppData\Local\Programs\Python\Python36-32\lib\site-packages\django\template\base.py:_resolve_lookup:878] [DEBUG]- Exception while resolving variable 'name' in template 'unknown'.
Traceback (most recent call last):
  File "C:\Users\Administrator.SC-201903241453\AppData\Local\Programs\Python\Python36-32\lib\site-packages\django\core\handlers\exception.py", line 35, in inner
    response = get_response(request)
  File "C:\Users\Administrator.SC-201903241453\AppData\Local\Programs\Python\Python36-32\lib\site-packages\django\core\handlers\base.py", line 113, in _get_response
    resolver_match = resolver.resolve(request.path_info)
  File "C:\Users\Administrator.SC-201903241453\AppData\Local\Programs\Python\Python36-32\lib\site-packages\django\urls\resolvers.py", line 523, in resolve
    raise Resolver404({'tried': tried, 'path': new_path})
django.urls.exceptions.Resolver404: {'tried': [[<URLResolver <URLPattern list> (admin:admin) 'admin/'>], [<URLResolver <module 'backend.version_1_0' from 'D:\\360MoveData\\Users\\Administrator.SC-201903241453\\Desktop\\backend-7-3\\backend\\version_1_0.py'> (None:None) 'api/v1.0/'>, <URLResolver <module 'apis.urls' from 'D:\\360MoveData\\Users\\Administrator.SC-201903241453\\Desktop\\backend-7-3\\apis\\urls.py'> (None:None) 'service/'>, <URLPattern 'weather'>], [<URLResolver <module 'backend.version_1_0' from 'D:\\360MoveData\\Users\\Administrator.SC-201903241453\\Desktop\\backend-7-3\\backend\\version_1_0.py'> (None:None) 'api/v1.0/'>, <URLResolver <module 'apis.urls' from 'D:\\360MoveData\\Users\\Administrator.SC-201903241453\\Desktop\\backend-7-3\\apis\\urls.py'> (None:None) 'service/'>, <URLPattern 'menu/user'>], [<URLResolver <module 'backend.version_1_0' from 'D:\\360MoveData\\Users\\Administrator.SC-201903241453\\Desktop\\backend-7-3\\backend\\version_1_0.py'> (None:None) 'api/v1.0/'>, <URLResolver <module 'apis.urls' from 'D:\\360MoveData\\Users\\Administrator.SC-201903241453\\Desktop\\backend-7-3\\apis\\urls.py'> (None:None) 'service/'>, <URLPattern 'menu/list'>], [<URLResolver <module 'backend.version_1_0' from 'D:\\360MoveData\\Users\\Administrator.SC-201903241453\\Desktop\\backend-7-3\\backend\\version_1_0.py'> (None:None) 'api/v1.0/'>, <URLResolver <module 'apis.urls' from 'D:\\360MoveData\\Users\\Administrator.SC-201903241453\\Desktop\\backend-7-3\\apis\\urls.py'> (None:None) 'service/'>, <URLPattern 'image'>], [<URLResolver <module 'backend.version_1_0' from 'D:\\360MoveData\\Users\\Administrator.SC-201903241453\\Desktop\\backend-7-3\\backend\\version_1_0.py'> (None:None) 'api/v1.0/'>, <URLResolver <module 'apis.urls' from 'D:\\360MoveData\\Users\\Administrator.SC-201903241453\\Desktop\\backend-7-3\\apis\\urls.py'> (None:None) 'service/'>, <URLPattern 'image/list'>], [<URLResolver <module 'backend.version_1_0' from 'D:\\360MoveData\\Users\\Administrator.SC-201903241453\\Desktop\\backend-7-3\\backend\\version_1_0.py'> (None:None) 'api/v1.0/'>, <URLResolver <module 'apis.urls' from 'D:\\360MoveData\\Users\\Administrator.SC-201903241453\\Desktop\\backend-7-3\\apis\\urls.py'> (None:None) 'service/'>, <URLPattern 'constellation'>], [<URLResolver <module 'backend.version_1_0' from 'D:\\360MoveData\\Users\\Administrator.SC-201903241453\\Desktop\\backend-7-3\\backend\\version_1_0.py'> (None:None) 'api/v1.0/'>, <URLResolver <module 'apis.urls' from 'D:\\360MoveData\\Users\\Administrator.SC-201903241453\\Desktop\\backend-7-3\\apis\\urls.py'> (None:None) 'service/'>, <URLPattern 'joke'>], [<URLResolver <module 'backend.version_1_0' from 'D:\\360MoveData\\Users\\Administrator.SC-201903241453\\Desktop\\backend-7-3\\backend\\version_1_0.py'> (None:None) 'api/v1.0/'>, <URLResolver <module 'apis.urls' from 'D:\\360MoveData\\Users\\Administrator.SC-201903241453\\Desktop\\backend-7-3\\apis\\urls.py'> (None:None) 'service/'>, <URLPattern 'today'>], [<URLResolver <module 'backend.version_1_0' from 'D:\\360MoveData\\Users\\Administrator.SC-201903241453\\Desktop\\backend-7-3\\backend\\version_1_0.py'> (None:None) 'api/v1.0/'>, <URLResolver <module 'apis.urls' from 'D:\\360MoveData\\Users\\Administrator.SC-201903241453\\Desktop\\backend-7-3\\apis\\urls.py'> (None:None) 'service/'>, <URLPattern 'stock'>], [<URLResolver <module 'backend.version_1_0' from 'D:\\360MoveData\\Users\\Administrator.SC-201903241453\\Desktop\\backend-7-3\\backend\\version_1_0.py'> (None:None) 'api/v1.0/'>, <URLResolver <module 'authorization.urls' from 'D:\\360MoveData\\Users\\Administrator.SC-201903241453\\Desktop\\backend-7-3\\authorization\\urls.py'> (None:None) 'auth/'>]], 'path': 'api/v1.0/service/'}

During handling of the above exception, another exception occurred:

Traceback (most recent call last):
  File "C:\Users\Administrator.SC-201903241453\AppData\Local\Programs\Python\Python36-32\lib\site-packages\django\template\base.py", line 835, in _resolve_lookup
    current = current[bit]
TypeError: 'URLResolver' object is not subscriptable

During handling of the above exception, another exception occurred:

Traceback (most recent call last):
  File "C:\Users\Administrator.SC-201903241453\AppData\Local\Programs\Python\Python36-32\lib\site-packages\django\template\base.py", line 843, in _resolve_lookup
    current = getattr(current, bit)
AttributeError: 'URLResolver' object has no attribute 'name'

During handling of the above exception, another exception occurred:

Traceback (most recent call last):
  File "C:\Users\Administrator.SC-201903241453\AppData\Local\Programs\Python\Python36-32\lib\site-packages\django\template\base.py", line 849, in _resolve_lookup
    current = current[int(bit)]
ValueError: invalid literal for int() with base 10: 'name'

During handling of the above exception, another exception occurred:

Traceback (most recent call last):
  File "C:\Users\Administrator.SC-201903241453\AppData\Local\Programs\Python\Python36-32\lib\site-packages\django\template\base.py", line 856, in _resolve_lookup
    (bit, current))  # missing attribute
django.template.base.VariableDoesNotExist: Failed lookup for key [name] in <URLResolver <URLPattern list> (admin:admin) 'admin/'>
2019-05-20 13:40:45,438 [Thread-22:6420] [C:\Users\Administrator.SC-201903241453\AppData\Local\Programs\Python\Python36-32\lib\site-packages\django\template\base.py:_resolve_lookup:878] [DEBUG]- Exception while resolving variable 'name' in template 'unknown'.
Traceback (most recent call last):
  File "C:\Users\Administrator.SC-201903241453\AppData\Local\Programs\Python\Python36-32\lib\site-packages\django\core\handlers\exception.py", line 35, in inner
    response = get_response(request)
  File "C:\Users\Administrator.SC-201903241453\AppData\Local\Programs\Python\Python36-32\lib\site-packages\django\core\handlers\base.py", line 113, in _get_response
    resolver_match = resolver.resolve(request.path_info)
  File "C:\Users\Administrator.SC-201903241453\AppData\Local\Programs\Python\Python36-32\lib\site-packages\django\urls\resolvers.py", line 523, in resolve
    raise Resolver404({'tried': tried, 'path': new_path})
django.urls.exceptions.Resolver404: {'tried': [[<URLResolver <URLPattern list> (admin:admin) 'admin/'>], [<URLResolver <module 'backend.version_1_0' from 'D:\\360MoveData\\Users\\Administrator.SC-201903241453\\Desktop\\backend-7-3\\backend\\version_1_0.py'> (None:None) 'api/v1.0/'>, <URLResolver <module 'apis.urls' from 'D:\\360MoveData\\Users\\Administrator.SC-201903241453\\Desktop\\backend-7-3\\apis\\urls.py'> (None:None) 'service/'>, <URLPattern 'weather'>], [<URLResolver <module 'backend.version_1_0' from 'D:\\360MoveData\\Users\\Administrator.SC-201903241453\\Desktop\\backend-7-3\\backend\\version_1_0.py'> (None:None) 'api/v1.0/'>, <URLResolver <module 'apis.urls' from 'D:\\360MoveData\\Users\\Administrator.SC-201903241453\\Desktop\\backend-7-3\\apis\\urls.py'> (None:None) 'service/'>, <URLPattern 'menu/user'>], [<URLResolver <module 'backend.version_1_0' from 'D:\\360MoveData\\Users\\Administrator.SC-201903241453\\Desktop\\backend-7-3\\backend\\version_1_0.py'> (None:None) 'api/v1.0/'>, <URLResolver <module 'apis.urls' from 'D:\\360MoveData\\Users\\Administrator.SC-201903241453\\Desktop\\backend-7-3\\apis\\urls.py'> (None:None) 'service/'>, <URLPattern 'menu/list'>], [<URLResolver <module 'backend.version_1_0' from 'D:\\360MoveData\\Users\\Administrator.SC-201903241453\\Desktop\\backend-7-3\\backend\\version_1_0.py'> (None:None) 'api/v1.0/'>, <URLResolver <module 'apis.urls' from 'D:\\360MoveData\\Users\\Administrator.SC-201903241453\\Desktop\\backend-7-3\\apis\\urls.py'> (None:None) 'service/'>, <URLPattern 'image'>], [<URLResolver <module 'backend.version_1_0' from 'D:\\360MoveData\\Users\\Administrator.SC-201903241453\\Desktop\\backend-7-3\\backend\\version_1_0.py'> (None:None) 'api/v1.0/'>, <URLResolver <module 'apis.urls' from 'D:\\360MoveData\\Users\\Administrator.SC-201903241453\\Desktop\\backend-7-3\\apis\\urls.py'> (None:None) 'service/'>, <URLPattern 'image/list'>], [<URLResolver <module 'backend.version_1_0' from 'D:\\360MoveData\\Users\\Administrator.SC-201903241453\\Desktop\\backend-7-3\\backend\\version_1_0.py'> (None:None) 'api/v1.0/'>, <URLResolver <module 'apis.urls' from 'D:\\360MoveData\\Users\\Administrator.SC-201903241453\\Desktop\\backend-7-3\\apis\\urls.py'> (None:None) 'service/'>, <URLPattern 'constellation'>], [<URLResolver <module 'backend.version_1_0' from 'D:\\360MoveData\\Users\\Administrator.SC-201903241453\\Desktop\\backend-7-3\\backend\\version_1_0.py'> (None:None) 'api/v1.0/'>, <URLResolver <module 'apis.urls' from 'D:\\360MoveData\\Users\\Administrator.SC-201903241453\\Desktop\\backend-7-3\\apis\\urls.py'> (None:None) 'service/'>, <URLPattern 'joke'>], [<URLResolver <module 'backend.version_1_0' from 'D:\\360MoveData\\Users\\Administrator.SC-201903241453\\Desktop\\backend-7-3\\backend\\version_1_0.py'> (None:None) 'api/v1.0/'>, <URLResolver <module 'apis.urls' from 'D:\\360MoveData\\Users\\Administrator.SC-201903241453\\Desktop\\backend-7-3\\apis\\urls.py'> (None:None) 'service/'>, <URLPattern 'today'>], [<URLResolver <module 'backend.version_1_0' from 'D:\\360MoveData\\Users\\Administrator.SC-201903241453\\Desktop\\backend-7-3\\backend\\version_1_0.py'> (None:None) 'api/v1.0/'>, <URLResolver <module 'apis.urls' from 'D:\\360MoveData\\Users\\Administrator.SC-201903241453\\Desktop\\backend-7-3\\apis\\urls.py'> (None:None) 'service/'>, <URLPattern 'stock'>], [<URLResolver <module 'backend.version_1_0' from 'D:\\360MoveData\\Users\\Administrator.SC-201903241453\\Desktop\\backend-7-3\\backend\\version_1_0.py'> (None:None) 'api/v1.0/'>, <URLResolver <module 'authorization.urls' from 'D:\\360MoveData\\Users\\Administrator.SC-201903241453\\Desktop\\backend-7-3\\authorization\\urls.py'> (None:None) 'auth/'>]], 'path': 'api/v1.0/service/'}

During handling of the above exception, another exception occurred:

Traceback (most recent call last):
  File "C:\Users\Administrator.SC-201903241453\AppData\Local\Programs\Python\Python36-32\lib\site-packages\django\template\base.py", line 835, in _resolve_lookup
    current = current[bit]
TypeError: 'URLResolver' object is not subscriptable

During handling of the above exception, another exception occurred:

Traceback (most recent call last):
  File "C:\Users\Administrator.SC-201903241453\AppData\Local\Programs\Python\Python36-32\lib\site-packages\django\template\base.py", line 843, in _resolve_lookup
    current = getattr(current, bit)
AttributeError: 'URLResolver' object has no attribute 'name'

During handling of the above exception, another exception occurred:

Traceback (most recent call last):
  File "C:\Users\Administrator.SC-201903241453\AppData\Local\Programs\Python\Python36-32\lib\site-packages\django\template\base.py", line 849, in _resolve_lookup
    current = current[int(bit)]
ValueError: invalid literal for int() with base 10: 'name'

During handling of the above exception, another exception occurred:

Traceback (most recent call last):
  File "C:\Users\Administrator.SC-201903241453\AppData\Local\Programs\Python\Python36-32\lib\site-packages\django\template\base.py", line 856, in _resolve_lookup
    (bit, current))  # missing attribute
django.template.base.VariableDoesNotExist: Failed lookup for key [name] in <URLResolver <module 'authorization.urls' from 'D:\\360MoveData\\Users\\Administrator.SC-201903241453\\Desktop\\backend-7-3\\authorization\\urls.py'> (None:None) 'auth/'>
2019-05-20 13:40:45,467 [Thread-22:6420] [C:\Users\Administrator.SC-201903241453\AppData\Local\Programs\Python\Python36-32\lib\site-packages\django\core\handlers\base.py:get_response:93] [WARNING]- Not Found: /api/v1.0/service/
2019-05-20 13:40:45,471 [Thread-22:6420] [C:\Users\Administrator.SC-201903241453\AppData\Local\Programs\Python\Python36-32\lib\site-packages\django\core\servers\basehttp.py:log_message:124] [WARNING]- "GET /api/v1.0/service/ HTTP/1.1" 404 4118
2019-05-20 13:40:52,868 [Thread-23:6424] [C:\Users\Administrator.SC-201903241453\AppData\Local\Programs\Python\Python36-32\lib\site-packages\django\db\backends\utils.py:execute:111] [DEBUG]- (0.000) SELECT @@SQL_AUTO_IS_NULL; args=None
2019-05-20 13:40:52,871 [Thread-23:6424] [C:\Users\Administrator.SC-201903241453\AppData\Local\Programs\Python\Python36-32\lib\site-packages\django\db\backends\utils.py:execute:111] [DEBUG]- (0.001) SET SESSION TRANSACTION ISOLATION LEVEL READ COMMITTED; args=None
2019-05-20 13:40:52,874 [Thread-23:6424] [C:\Users\Administrator.SC-201903241453\AppData\Local\Programs\Python\Python36-32\lib\site-packages\django\db\backends\utils.py:execute:111] [DEBUG]- (0.001) None; args=()
2019-05-20 13:40:52,876 [Thread-23:6424] [C:\Users\Administrator.SC-201903241453\AppData\Local\Programs\Python\Python36-32\lib\site-packages\django\core\handlers\exception.py:handle_uncaught_exception:118] [ERROR]- Internal Server Error: /api/v1.0/service/menu/list
Traceback (most recent call last):
  File "C:\Users\Administrator.SC-201903241453\AppData\Local\Programs\Python\Python36-32\lib\site-packages\django\db\backends\utils.py", line 85, in _execute
    return self.cursor.execute(sql, params)
  File "C:\Users\Administrator.SC-201903241453\AppData\Local\Programs\Python\Python36-32\lib\site-packages\django\db\backends\mysql\base.py", line 71, in execute
    return self.cursor.execute(query, args)
  File "C:\Users\Administrator.SC-201903241453\AppData\Local\Programs\Python\Python36-32\lib\site-packages\MySQLdb\cursors.py", line 206, in execute
    res = self._query(query)
  File "C:\Users\Administrator.SC-201903241453\AppData\Local\Programs\Python\Python36-32\lib\site-packages\MySQLdb\cursors.py", line 312, in _query
    db.query(q)
  File "C:\Users\Administrator.SC-201903241453\AppData\Local\Programs\Python\Python36-32\lib\site-packages\MySQLdb\connections.py", line 224, in query
    _mysql.connection.query(self, query)
MySQLdb._exceptions.ProgrammingError: (1146, "Table 'backend.apis_app' doesn't exist")

The above exception was the direct cause of the following exception:

Traceback (most recent call last):
  File "C:\Users\Administrator.SC-201903241453\AppData\Local\Programs\Python\Python36-32\lib\site-packages\django\core\handlers\exception.py", line 35, in inner
    response = get_response(request)
  File "C:\Users\Administrator.SC-201903241453\AppData\Local\Programs\Python\Python36-32\lib\site-packages\django\core\handlers\base.py", line 128, in _get_response
    response = self.process_exception_by_middleware(e, request)
  File "C:\Users\Administrator.SC-201903241453\AppData\Local\Programs\Python\Python36-32\lib\site-packages\django\core\handlers\base.py", line 126, in _get_response
    response = wrapped_callback(request, *callback_args, **callback_kwargs)
  File "D:\360MoveData\Users\Administrator.SC-201903241453\Desktop\backend-7-3\apis\views\menu.py", line 37, in get_menu
    for app in query_set:
  File "C:\Users\Administrator.SC-201903241453\AppData\Local\Programs\Python\Python36-32\lib\site-packages\django\db\models\query.py", line 272, in __iter__
    self._fetch_all()
  File "C:\Users\Administrator.SC-201903241453\AppData\Local\Programs\Python\Python36-32\lib\site-packages\django\db\models\query.py", line 1179, in _fetch_all
    self._result_cache = list(self._iterable_class(self))
  File "C:\Users\Administrator.SC-201903241453\AppData\Local\Programs\Python\Python36-32\lib\site-packages\django\db\models\query.py", line 54, in __iter__
    results = compiler.execute_sql(chunked_fetch=self.chunked_fetch, chunk_size=self.chunk_size)
  File "C:\Users\Administrator.SC-201903241453\AppData\Local\Programs\Python\Python36-32\lib\site-packages\django\db\models\sql\compiler.py", line 1063, in execute_sql
    cursor.execute(sql, params)
  File "C:\Users\Administrator.SC-201903241453\AppData\Local\Programs\Python\Python36-32\lib\site-packages\django\db\backends\utils.py", line 100, in execute
    return super().execute(sql, params)
  File "C:\Users\Administrator.SC-201903241453\AppData\Local\Programs\Python\Python36-32\lib\site-packages\django\db\backends\utils.py", line 68, in execute
    return self._execute_with_wrappers(sql, params, many=False, executor=self._execute)
  File "C:\Users\Administrator.SC-201903241453\AppData\Local\Programs\Python\Python36-32\lib\site-packages\django\db\backends\utils.py", line 77, in _execute_with_wrappers
    return executor(sql, params, many, context)
  File "C:\Users\Administrator.SC-201903241453\AppData\Local\Programs\Python\Python36-32\lib\site-packages\django\db\backends\utils.py", line 85, in _execute
    return self.cursor.execute(sql, params)
  File "C:\Users\Administrator.SC-201903241453\AppData\Local\Programs\Python\Python36-32\lib\site-packages\django\db\utils.py", line 89, in __exit__
    raise dj_exc_value.with_traceback(traceback) from exc_value
  File "C:\Users\Administrator.SC-201903241453\AppData\Local\Programs\Python\Python36-32\lib\site-packages\django\db\backends\utils.py", line 85, in _execute
    return self.cursor.execute(sql, params)
  File "C:\Users\Administrator.SC-201903241453\AppData\Local\Programs\Python\Python36-32\lib\site-packages\django\db\backends\mysql\base.py", line 71, in execute
    return self.cursor.execute(query, args)
  File "C:\Users\Administrator.SC-201903241453\AppData\Local\Programs\Python\Python36-32\lib\site-packages\MySQLdb\cursors.py", line 206, in execute
    res = self._query(query)
  File "C:\Users\Administrator.SC-201903241453\AppData\Local\Programs\Python\Python36-32\lib\site-packages\MySQLdb\cursors.py", line 312, in _query
    db.query(q)
  File "C:\Users\Administrator.SC-201903241453\AppData\Local\Programs\Python\Python36-32\lib\site-packages\MySQLdb\connections.py", line 224, in query
    _mysql.connection.query(self, query)
django.db.utils.ProgrammingError: (1146, "Table 'backend.apis_app' doesn't exist")
2019-05-20 13:40:52,948 [Thread-23:6424] [C:\Users\Administrator.SC-201903241453\AppData\Local\Programs\Python\Python36-32\lib\site-packages\django\db\backends\utils.py:execute:111] [DEBUG]- (0.001) None; args=()
2019-05-20 13:40:52,952 [Thread-23:6424] [C:\Users\Administrator.SC-201903241453\AppData\Local\Programs\Python\Python36-32\lib\site-packages\django\db\backends\utils.py:execute:111] [DEBUG]- (0.001) None; args=()
2019-05-20 13:40:52,955 [Thread-23:6424] [C:\Users\Administrator.SC-201903241453\AppData\Local\Programs\Python\Python36-32\lib\site-packages\django\db\backends\utils.py:execute:111] [DEBUG]- (0.001) None; args=()
2019-05-20 13:40:52,958 [Thread-23:6424] [C:\Users\Administrator.SC-201903241453\AppData\Local\Programs\Python\Python36-32\lib\site-packages\django\db\backends\utils.py:execute:111] [DEBUG]- (0.001) None; args=()
2019-05-20 13:40:52,962 [Thread-23:6424] [C:\Users\Administrator.SC-201903241453\AppData\Local\Programs\Python\Python36-32\lib\site-packages\django\db\backends\utils.py:execute:111] [DEBUG]- (0.000) SELECT VERSION(); args=None
2019-05-20 13:40:52,964 [Thread-23:6424] [C:\Users\Administrator.SC-201903241453\AppData\Local\Programs\Python\Python36-32\lib\site-packages\django\db\backends\utils.py:execute:111] [DEBUG]- (0.001) SELECT `django_session`.`session_key`, `django_session`.`session_data`, `django_session`.`expire_date` FROM `django_session` WHERE (`django_session`.`session_key` = '7m9ujkc2e2in3a9sedd9fv82zwrnzj0z' AND `django_session`.`expire_date` > '2019-05-20 05:40:52'); args=('7m9ujkc2e2in3a9sedd9fv82zwrnzj0z', '2019-05-20 05:40:52')
2019-05-20 13:40:52,972 [Thread-23:6424] [C:\Users\Administrator.SC-201903241453\AppData\Local\Programs\Python\Python36-32\lib\site-packages\django\db\backends\utils.py:execute:111] [DEBUG]- (0.003) SELECT `auth_user`.`id`, `auth_user`.`password`, `auth_user`.`last_login`, `auth_user`.`is_superuser`, `auth_user`.`username`, `auth_user`.`first_name`, `auth_user`.`last_name`, `auth_user`.`email`, `auth_user`.`is_staff`, `auth_user`.`is_active`, `auth_user`.`date_joined` FROM `auth_user` WHERE `auth_user`.`id` = 1; args=(1,)
2019-05-20 13:40:53,054 [Thread-23:6424] [C:\Users\Administrator.SC-201903241453\AppData\Local\Programs\Python\Python36-32\lib\site-packages\django\core\servers\basehttp.py:log_message:124] [ERROR]- "GET /api/v1.0/service/menu/list HTTP/1.1" 500 148688
2019-05-20 13:41:17,099 [Thread-27:3820] [C:\Users\Administrator.SC-201903241453\AppData\Local\Programs\Python\Python36-32\lib\site-packages\django\template\base.py:_resolve_lookup:878] [DEBUG]- Exception while resolving variable 'name' in template 'unknown'.
Traceback (most recent call last):
  File "C:\Users\Administrator.SC-201903241453\AppData\Local\Programs\Python\Python36-32\lib\site-packages\django\core\handlers\exception.py", line 35, in inner
    response = get_response(request)
  File "C:\Users\Administrator.SC-201903241453\AppData\Local\Programs\Python\Python36-32\lib\site-packages\django\core\handlers\base.py", line 113, in _get_response
    resolver_match = resolver.resolve(request.path_info)
  File "C:\Users\Administrator.SC-201903241453\AppData\Local\Programs\Python\Python36-32\lib\site-packages\django\urls\resolvers.py", line 523, in resolve
    raise Resolver404({'tried': tried, 'path': new_path})
django.urls.exceptions.Resolver404: {'tried': [[<URLResolver <URLPattern list> (admin:admin) 'admin/'>], [<URLResolver <module 'backend.version_1_0' from 'D:\\360MoveData\\Users\\Administrator.SC-201903241453\\Desktop\\backend-7-3\\backend\\version_1_0.py'> (None:None) 'api/v1.0/'>, <URLResolver <module 'apis.urls' from 'D:\\360MoveData\\Users\\Administrator.SC-201903241453\\Desktop\\backend-7-3\\apis\\urls.py'> (None:None) 'service/'>, <URLPattern 'weather'>], [<URLResolver <module 'backend.version_1_0' from 'D:\\360MoveData\\Users\\Administrator.SC-201903241453\\Desktop\\backend-7-3\\backend\\version_1_0.py'> (None:None) 'api/v1.0/'>, <URLResolver <module 'apis.urls' from 'D:\\360MoveData\\Users\\Administrator.SC-201903241453\\Desktop\\backend-7-3\\apis\\urls.py'> (None:None) 'service/'>, <URLPattern 'menu/user'>], [<URLResolver <module 'backend.version_1_0' from 'D:\\360MoveData\\Users\\Administrator.SC-201903241453\\Desktop\\backend-7-3\\backend\\version_1_0.py'> (None:None) 'api/v1.0/'>, <URLResolver <module 'apis.urls' from 'D:\\360MoveData\\Users\\Administrator.SC-201903241453\\Desktop\\backend-7-3\\apis\\urls.py'> (None:None) 'service/'>, <URLPattern 'menu/list'>], [<URLResolver <module 'backend.version_1_0' from 'D:\\360MoveData\\Users\\Administrator.SC-201903241453\\Desktop\\backend-7-3\\backend\\version_1_0.py'> (None:None) 'api/v1.0/'>, <URLResolver <module 'apis.urls' from 'D:\\360MoveData\\Users\\Administrator.SC-201903241453\\Desktop\\backend-7-3\\apis\\urls.py'> (None:None) 'service/'>, <URLPattern 'image'>], [<URLResolver <module 'backend.version_1_0' from 'D:\\360MoveData\\Users\\Administrator.SC-201903241453\\Desktop\\backend-7-3\\backend\\version_1_0.py'> (None:None) 'api/v1.0/'>, <URLResolver <module 'apis.urls' from 'D:\\360MoveData\\Users\\Administrator.SC-201903241453\\Desktop\\backend-7-3\\apis\\urls.py'> (None:None) 'service/'>, <URLPattern 'image/list'>], [<URLResolver <module 'backend.version_1_0' from 'D:\\360MoveData\\Users\\Administrator.SC-201903241453\\Desktop\\backend-7-3\\backend\\version_1_0.py'> (None:None) 'api/v1.0/'>, <URLResolver <module 'apis.urls' from 'D:\\360MoveData\\Users\\Administrator.SC-201903241453\\Desktop\\backend-7-3\\apis\\urls.py'> (None:None) 'service/'>, <URLPattern 'constellation'>], [<URLResolver <module 'backend.version_1_0' from 'D:\\360MoveData\\Users\\Administrator.SC-201903241453\\Desktop\\backend-7-3\\backend\\version_1_0.py'> (None:None) 'api/v1.0/'>, <URLResolver <module 'apis.urls' from 'D:\\360MoveData\\Users\\Administrator.SC-201903241453\\Desktop\\backend-7-3\\apis\\urls.py'> (None:None) 'service/'>, <URLPattern 'joke'>], [<URLResolver <module 'backend.version_1_0' from 'D:\\360MoveData\\Users\\Administrator.SC-201903241453\\Desktop\\backend-7-3\\backend\\version_1_0.py'> (None:None) 'api/v1.0/'>, <URLResolver <module 'apis.urls' from 'D:\\360MoveData\\Users\\Administrator.SC-201903241453\\Desktop\\backend-7-3\\apis\\urls.py'> (None:None) 'service/'>, <URLPattern 'today'>], [<URLResolver <module 'backend.version_1_0' from 'D:\\360MoveData\\Users\\Administrator.SC-201903241453\\Desktop\\backend-7-3\\backend\\version_1_0.py'> (None:None) 'api/v1.0/'>, <URLResolver <module 'apis.urls' from 'D:\\360MoveData\\Users\\Administrator.SC-201903241453\\Desktop\\backend-7-3\\apis\\urls.py'> (None:None) 'service/'>, <URLPattern 'stock'>], [<URLResolver <module 'backend.version_1_0' from 'D:\\360MoveData\\Users\\Administrator.SC-201903241453\\Desktop\\backend-7-3\\backend\\version_1_0.py'> (None:None) 'api/v1.0/'>, <URLResolver <module 'authorization.urls' from 'D:\\360MoveData\\Users\\Administrator.SC-201903241453\\Desktop\\backend-7-3\\authorization\\urls.py'> (None:None) 'auth/'>]], 'path': 'api/v1.0/service/admin'}

During handling of the above exception, another exception occurred:

Traceback (most recent call last):
  File "C:\Users\Administrator.SC-201903241453\AppData\Local\Programs\Python\Python36-32\lib\site-packages\django\template\base.py", line 835, in _resolve_lookup
    current = current[bit]
TypeError: 'URLResolver' object is not subscriptable

During handling of the above exception, another exception occurred:

Traceback (most recent call last):
  File "C:\Users\Administrator.SC-201903241453\AppData\Local\Programs\Python\Python36-32\lib\site-packages\django\template\base.py", line 843, in _resolve_lookup
    current = getattr(current, bit)
AttributeError: 'URLResolver' object has no attribute 'name'

During handling of the above exception, another exception occurred:

Traceback (most recent call last):
  File "C:\Users\Administrator.SC-201903241453\AppData\Local\Programs\Python\Python36-32\lib\site-packages\django\template\base.py", line 849, in _resolve_lookup
    current = current[int(bit)]
ValueError: invalid literal for int() with base 10: 'name'

During handling of the above exception, another exception occurred:

Traceback (most recent call last):
  File "C:\Users\Administrator.SC-201903241453\AppData\Local\Programs\Python\Python36-32\lib\site-packages\django\template\base.py", line 856, in _resolve_lookup
    (bit, current))  # missing attribute
django.template.base.VariableDoesNotExist: Failed lookup for key [name] in <URLResolver <URLPattern list> (admin:admin) 'admin/'>
2019-05-20 13:41:17,132 [Thread-27:3820] [C:\Users\Administrator.SC-201903241453\AppData\Local\Programs\Python\Python36-32\lib\site-packages\django\template\base.py:_resolve_lookup:878] [DEBUG]- Exception while resolving variable 'name' in template 'unknown'.
Traceback (most recent call last):
  File "C:\Users\Administrator.SC-201903241453\AppData\Local\Programs\Python\Python36-32\lib\site-packages\django\core\handlers\exception.py", line 35, in inner
    response = get_response(request)
  File "C:\Users\Administrator.SC-201903241453\AppData\Local\Programs\Python\Python36-32\lib\site-packages\django\core\handlers\base.py", line 113, in _get_response
    resolver_match = resolver.resolve(request.path_info)
  File "C:\Users\Administrator.SC-201903241453\AppData\Local\Programs\Python\Python36-32\lib\site-packages\django\urls\resolvers.py", line 523, in resolve
    raise Resolver404({'tried': tried, 'path': new_path})
django.urls.exceptions.Resolver404: {'tried': [[<URLResolver <URLPattern list> (admin:admin) 'admin/'>], [<URLResolver <module 'backend.version_1_0' from 'D:\\360MoveData\\Users\\Administrator.SC-201903241453\\Desktop\\backend-7-3\\backend\\version_1_0.py'> (None:None) 'api/v1.0/'>, <URLResolver <module 'apis.urls' from 'D:\\360MoveData\\Users\\Administrator.SC-201903241453\\Desktop\\backend-7-3\\apis\\urls.py'> (None:None) 'service/'>, <URLPattern 'weather'>], [<URLResolver <module 'backend.version_1_0' from 'D:\\360MoveData\\Users\\Administrator.SC-201903241453\\Desktop\\backend-7-3\\backend\\version_1_0.py'> (None:None) 'api/v1.0/'>, <URLResolver <module 'apis.urls' from 'D:\\360MoveData\\Users\\Administrator.SC-201903241453\\Desktop\\backend-7-3\\apis\\urls.py'> (None:None) 'service/'>, <URLPattern 'menu/user'>], [<URLResolver <module 'backend.version_1_0' from 'D:\\360MoveData\\Users\\Administrator.SC-201903241453\\Desktop\\backend-7-3\\backend\\version_1_0.py'> (None:None) 'api/v1.0/'>, <URLResolver <module 'apis.urls' from 'D:\\360MoveData\\Users\\Administrator.SC-201903241453\\Desktop\\backend-7-3\\apis\\urls.py'> (None:None) 'service/'>, <URLPattern 'menu/list'>], [<URLResolver <module 'backend.version_1_0' from 'D:\\360MoveData\\Users\\Administrator.SC-201903241453\\Desktop\\backend-7-3\\backend\\version_1_0.py'> (None:None) 'api/v1.0/'>, <URLResolver <module 'apis.urls' from 'D:\\360MoveData\\Users\\Administrator.SC-201903241453\\Desktop\\backend-7-3\\apis\\urls.py'> (None:None) 'service/'>, <URLPattern 'image'>], [<URLResolver <module 'backend.version_1_0' from 'D:\\360MoveData\\Users\\Administrator.SC-201903241453\\Desktop\\backend-7-3\\backend\\version_1_0.py'> (None:None) 'api/v1.0/'>, <URLResolver <module 'apis.urls' from 'D:\\360MoveData\\Users\\Administrator.SC-201903241453\\Desktop\\backend-7-3\\apis\\urls.py'> (None:None) 'service/'>, <URLPattern 'image/list'>], [<URLResolver <module 'backend.version_1_0' from 'D:\\360MoveData\\Users\\Administrator.SC-201903241453\\Desktop\\backend-7-3\\backend\\version_1_0.py'> (None:None) 'api/v1.0/'>, <URLResolver <module 'apis.urls' from 'D:\\360MoveData\\Users\\Administrator.SC-201903241453\\Desktop\\backend-7-3\\apis\\urls.py'> (None:None) 'service/'>, <URLPattern 'constellation'>], [<URLResolver <module 'backend.version_1_0' from 'D:\\360MoveData\\Users\\Administrator.SC-201903241453\\Desktop\\backend-7-3\\backend\\version_1_0.py'> (None:None) 'api/v1.0/'>, <URLResolver <module 'apis.urls' from 'D:\\360MoveData\\Users\\Administrator.SC-201903241453\\Desktop\\backend-7-3\\apis\\urls.py'> (None:None) 'service/'>, <URLPattern 'joke'>], [<URLResolver <module 'backend.version_1_0' from 'D:\\360MoveData\\Users\\Administrator.SC-201903241453\\Desktop\\backend-7-3\\backend\\version_1_0.py'> (None:None) 'api/v1.0/'>, <URLResolver <module 'apis.urls' from 'D:\\360MoveData\\Users\\Administrator.SC-201903241453\\Desktop\\backend-7-3\\apis\\urls.py'> (None:None) 'service/'>, <URLPattern 'today'>], [<URLResolver <module 'backend.version_1_0' from 'D:\\360MoveData\\Users\\Administrator.SC-201903241453\\Desktop\\backend-7-3\\backend\\version_1_0.py'> (None:None) 'api/v1.0/'>, <URLResolver <module 'apis.urls' from 'D:\\360MoveData\\Users\\Administrator.SC-201903241453\\Desktop\\backend-7-3\\apis\\urls.py'> (None:None) 'service/'>, <URLPattern 'stock'>], [<URLResolver <module 'backend.version_1_0' from 'D:\\360MoveData\\Users\\Administrator.SC-201903241453\\Desktop\\backend-7-3\\backend\\version_1_0.py'> (None:None) 'api/v1.0/'>, <URLResolver <module 'authorization.urls' from 'D:\\360MoveData\\Users\\Administrator.SC-201903241453\\Desktop\\backend-7-3\\authorization\\urls.py'> (None:None) 'auth/'>]], 'path': 'api/v1.0/service/admin'}

During handling of the above exception, another exception occurred:

Traceback (most recent call last):
  File "C:\Users\Administrator.SC-201903241453\AppData\Local\Programs\Python\Python36-32\lib\site-packages\django\template\base.py", line 835, in _resolve_lookup
    current = current[bit]
TypeError: 'URLResolver' object is not subscriptable

During handling of the above exception, another exception occurred:

Traceback (most recent call last):
  File "C:\Users\Administrator.SC-201903241453\AppData\Local\Programs\Python\Python36-32\lib\site-packages\django\template\base.py", line 843, in _resolve_lookup
    current = getattr(current, bit)
AttributeError: 'URLResolver' object has no attribute 'name'

During handling of the above exception, another exception occurred:

Traceback (most recent call last):
  File "C:\Users\Administrator.SC-201903241453\AppData\Local\Programs\Python\Python36-32\lib\site-packages\django\template\base.py", line 849, in _resolve_lookup
    current = current[int(bit)]
ValueError: invalid literal for int() with base 10: 'name'

During handling of the above exception, another exception occurred:

Traceback (most recent call last):
  File "C:\Users\Administrator.SC-201903241453\AppData\Local\Programs\Python\Python36-32\lib\site-packages\django\template\base.py", line 856, in _resolve_lookup
    (bit, current))  # missing attribute
django.template.base.VariableDoesNotExist: Failed lookup for key [name] in <URLResolver <module 'authorization.urls' from 'D:\\360MoveData\\Users\\Administrator.SC-201903241453\\Desktop\\backend-7-3\\authorization\\urls.py'> (None:None) 'auth/'>
2019-05-20 13:41:17,167 [Thread-27:3820] [C:\Users\Administrator.SC-201903241453\AppData\Local\Programs\Python\Python36-32\lib\site-packages\django\core\handlers\base.py:get_response:93] [WARNING]- Not Found: /api/v1.0/service/admin
2019-05-20 13:41:17,170 [Thread-27:3820] [C:\Users\Administrator.SC-201903241453\AppData\Local\Programs\Python\Python36-32\lib\site-packages\django\core\servers\basehttp.py:log_message:124] [WARNING]- "GET /api/v1.0/service/admin HTTP/1.1" 404 4133
2019-05-20 13:41:36,782 [Thread-30:7196] [C:\Users\Administrator.SC-201903241453\AppData\Local\Programs\Python\Python36-32\lib\site-packages\django\core\handlers\exception.py:handle_uncaught_exception:118] [ERROR]- Internal Server Error: /api/v1.0/service/image
Traceback (most recent call last):
  File "C:\Users\Administrator.SC-201903241453\AppData\Local\Programs\Python\Python36-32\lib\site-packages\django\core\handlers\exception.py", line 35, in inner
    response = get_response(request)
  File "C:\Users\Administrator.SC-201903241453\AppData\Local\Programs\Python\Python36-32\lib\site-packages\django\core\handlers\base.py", line 128, in _get_response
    response = self.process_exception_by_middleware(e, request)
  File "C:\Users\Administrator.SC-201903241453\AppData\Local\Programs\Python\Python36-32\lib\site-packages\django\core\handlers\base.py", line 126, in _get_response
    response = wrapped_callback(request, *callback_args, **callback_kwargs)
  File "C:\Users\Administrator.SC-201903241453\AppData\Local\Programs\Python\Python36-32\lib\site-packages\django\views\generic\base.py", line 69, in view
    return self.dispatch(request, *args, **kwargs)
  File "C:\Users\Administrator.SC-201903241453\AppData\Local\Programs\Python\Python36-32\lib\site-packages\django\views\generic\base.py", line 89, in dispatch
    return handler(request, *args, **kwargs)
  File "D:\360MoveData\Users\Administrator.SC-201903241453\Desktop\backend-7-3\apis\views\image.py", line 34, in get
    imgfile = os.path.join(settings.IMAGES_DIR, md5 + '.jpg')
TypeError: unsupported operand type(s) for +: 'NoneType' and 'str'
2019-05-20 13:41:36,823 [Thread-30:7196] [C:\Users\Administrator.SC-201903241453\AppData\Local\Programs\Python\Python36-32\lib\site-packages\django\db\backends\utils.py:execute:111] [DEBUG]- (0.001) SELECT @@SQL_AUTO_IS_NULL; args=None
2019-05-20 13:41:36,826 [Thread-30:7196] [C:\Users\Administrator.SC-201903241453\AppData\Local\Programs\Python\Python36-32\lib\site-packages\django\db\backends\utils.py:execute:111] [DEBUG]- (0.001) SET SESSION TRANSACTION ISOLATION LEVEL READ COMMITTED; args=None
2019-05-20 13:41:36,831 [Thread-30:7196] [C:\Users\Administrator.SC-201903241453\AppData\Local\Programs\Python\Python36-32\lib\site-packages\django\db\backends\utils.py:execute:111] [DEBUG]- (0.001) SELECT VERSION(); args=None
2019-05-20 13:41:36,837 [Thread-30:7196] [C:\Users\Administrator.SC-201903241453\AppData\Local\Programs\Python\Python36-32\lib\site-packages\django\db\backends\utils.py:execute:111] [DEBUG]- (0.001) SET SESSION TRANSACTION ISOLATION LEVEL READ COMMITTED; args=None
2019-05-20 13:41:36,839 [Thread-30:7196] [C:\Users\Administrator.SC-201903241453\AppData\Local\Programs\Python\Python36-32\lib\site-packages\django\db\backends\utils.py:execute:111] [DEBUG]- (0.001) SELECT `django_session`.`session_key`, `django_session`.`session_data`, `django_session`.`expire_date` FROM `django_session` WHERE (`django_session`.`session_key` = '7m9ujkc2e2in3a9sedd9fv82zwrnzj0z' AND `django_session`.`expire_date` > '2019-05-20 05:41:36'); args=('7m9ujkc2e2in3a9sedd9fv82zwrnzj0z', '2019-05-20 05:41:36')
2019-05-20 13:41:36,843 [Thread-30:7196] [C:\Users\Administrator.SC-201903241453\AppData\Local\Programs\Python\Python36-32\lib\site-packages\django\db\backends\utils.py:execute:111] [DEBUG]- (0.001) SELECT `auth_user`.`id`, `auth_user`.`password`, `auth_user`.`last_login`, `auth_user`.`is_superuser`, `auth_user`.`username`, `auth_user`.`first_name`, `auth_user`.`last_name`, `auth_user`.`email`, `auth_user`.`is_staff`, `auth_user`.`is_active`, `auth_user`.`date_joined` FROM `auth_user` WHERE `auth_user`.`id` = 1; args=(1,)
2019-05-20 13:41:36,887 [Thread-30:7196] [C:\Users\Administrator.SC-201903241453\AppData\Local\Programs\Python\Python36-32\lib\site-packages\django\core\servers\basehttp.py:log_message:124] [ERROR]- "GET /api/v1.0/service/image HTTP/1.1" 500 75757
2019-05-20 13:41:49,892 [Thread-33:4184] [C:\Users\Administrator.SC-201903241453\AppData\Local\Programs\Python\Python36-32\lib\site-packages\django\template\base.py:_resolve_lookup:878] [DEBUG]- Exception while resolving variable 'name' in template 'unknown'.
Traceback (most recent call last):
  File "C:\Users\Administrator.SC-201903241453\AppData\Local\Programs\Python\Python36-32\lib\site-packages\django\core\handlers\exception.py", line 35, in inner
    response = get_response(request)
  File "C:\Users\Administrator.SC-201903241453\AppData\Local\Programs\Python\Python36-32\lib\site-packages\django\core\handlers\base.py", line 113, in _get_response
    resolver_match = resolver.resolve(request.path_info)
  File "C:\Users\Administrator.SC-201903241453\AppData\Local\Programs\Python\Python36-32\lib\site-packages\django\urls\resolvers.py", line 523, in resolve
    raise Resolver404({'tried': tried, 'path': new_path})
django.urls.exceptions.Resolver404: {'tried': [[<URLResolver <URLPattern list> (admin:admin) 'admin/'>], [<URLResolver <module 'backend.version_1_0' from 'D:\\360MoveData\\Users\\Administrator.SC-201903241453\\Desktop\\backend-7-3\\backend\\version_1_0.py'> (None:None) 'api/v1.0/'>, <URLResolver <module 'apis.urls' from 'D:\\360MoveData\\Users\\Administrator.SC-201903241453\\Desktop\\backend-7-3\\apis\\urls.py'> (None:None) 'service/'>, <URLPattern 'weather'>], [<URLResolver <module 'backend.version_1_0' from 'D:\\360MoveData\\Users\\Administrator.SC-201903241453\\Desktop\\backend-7-3\\backend\\version_1_0.py'> (None:None) 'api/v1.0/'>, <URLResolver <module 'apis.urls' from 'D:\\360MoveData\\Users\\Administrator.SC-201903241453\\Desktop\\backend-7-3\\apis\\urls.py'> (None:None) 'service/'>, <URLPattern 'menu/user'>], [<URLResolver <module 'backend.version_1_0' from 'D:\\360MoveData\\Users\\Administrator.SC-201903241453\\Desktop\\backend-7-3\\backend\\version_1_0.py'> (None:None) 'api/v1.0/'>, <URLResolver <module 'apis.urls' from 'D:\\360MoveData\\Users\\Administrator.SC-201903241453\\Desktop\\backend-7-3\\apis\\urls.py'> (None:None) 'service/'>, <URLPattern 'menu/list'>], [<URLResolver <module 'backend.version_1_0' from 'D:\\360MoveData\\Users\\Administrator.SC-201903241453\\Desktop\\backend-7-3\\backend\\version_1_0.py'> (None:None) 'api/v1.0/'>, <URLResolver <module 'apis.urls' from 'D:\\360MoveData\\Users\\Administrator.SC-201903241453\\Desktop\\backend-7-3\\apis\\urls.py'> (None:None) 'service/'>, <URLPattern 'image'>], [<URLResolver <module 'backend.version_1_0' from 'D:\\360MoveData\\Users\\Administrator.SC-201903241453\\Desktop\\backend-7-3\\backend\\version_1_0.py'> (None:None) 'api/v1.0/'>, <URLResolver <module 'apis.urls' from 'D:\\360MoveData\\Users\\Administrator.SC-201903241453\\Desktop\\backend-7-3\\apis\\urls.py'> (None:None) 'service/'>, <URLPattern 'image/list'>], [<URLResolver <module 'backend.version_1_0' from 'D:\\360MoveData\\Users\\Administrator.SC-201903241453\\Desktop\\backend-7-3\\backend\\version_1_0.py'> (None:None) 'api/v1.0/'>, <URLResolver <module 'apis.urls' from 'D:\\360MoveData\\Users\\Administrator.SC-201903241453\\Desktop\\backend-7-3\\apis\\urls.py'> (None:None) 'service/'>, <URLPattern 'constellation'>], [<URLResolver <module 'backend.version_1_0' from 'D:\\360MoveData\\Users\\Administrator.SC-201903241453\\Desktop\\backend-7-3\\backend\\version_1_0.py'> (None:None) 'api/v1.0/'>, <URLResolver <module 'apis.urls' from 'D:\\360MoveData\\Users\\Administrator.SC-201903241453\\Desktop\\backend-7-3\\apis\\urls.py'> (None:None) 'service/'>, <URLPattern 'joke'>], [<URLResolver <module 'backend.version_1_0' from 'D:\\360MoveData\\Users\\Administrator.SC-201903241453\\Desktop\\backend-7-3\\backend\\version_1_0.py'> (None:None) 'api/v1.0/'>, <URLResolver <module 'apis.urls' from 'D:\\360MoveData\\Users\\Administrator.SC-201903241453\\Desktop\\backend-7-3\\apis\\urls.py'> (None:None) 'service/'>, <URLPattern 'today'>], [<URLResolver <module 'backend.version_1_0' from 'D:\\360MoveData\\Users\\Administrator.SC-201903241453\\Desktop\\backend-7-3\\backend\\version_1_0.py'> (None:None) 'api/v1.0/'>, <URLResolver <module 'apis.urls' from 'D:\\360MoveData\\Users\\Administrator.SC-201903241453\\Desktop\\backend-7-3\\apis\\urls.py'> (None:None) 'service/'>, <URLPattern 'stock'>], [<URLResolver <module 'backend.version_1_0' from 'D:\\360MoveData\\Users\\Administrator.SC-201903241453\\Desktop\\backend-7-3\\backend\\version_1_0.py'> (None:None) 'api/v1.0/'>, <URLResolver <module 'authorization.urls' from 'D:\\360MoveData\\Users\\Administrator.SC-201903241453\\Desktop\\backend-7-3\\authorization\\urls.py'> (None:None) 'auth/'>]], 'path': 'api/v1.0/service/'}

During handling of the above exception, another exception occurred:

Traceback (most recent call last):
  File "C:\Users\Administrator.SC-201903241453\AppData\Local\Programs\Python\Python36-32\lib\site-packages\django\template\base.py", line 835, in _resolve_lookup
    current = current[bit]
TypeError: 'URLResolver' object is not subscriptable

During handling of the above exception, another exception occurred:

Traceback (most recent call last):
  File "C:\Users\Administrator.SC-201903241453\AppData\Local\Programs\Python\Python36-32\lib\site-packages\django\template\base.py", line 843, in _resolve_lookup
    current = getattr(current, bit)
AttributeError: 'URLResolver' object has no attribute 'name'

During handling of the above exception, another exception occurred:

Traceback (most recent call last):
  File "C:\Users\Administrator.SC-201903241453\AppData\Local\Programs\Python\Python36-32\lib\site-packages\django\template\base.py", line 849, in _resolve_lookup
    current = current[int(bit)]
ValueError: invalid literal for int() with base 10: 'name'

During handling of the above exception, another exception occurred:

Traceback (most recent call last):
  File "C:\Users\Administrator.SC-201903241453\AppData\Local\Programs\Python\Python36-32\lib\site-packages\django\template\base.py", line 856, in _resolve_lookup
    (bit, current))  # missing attribute
django.template.base.VariableDoesNotExist: Failed lookup for key [name] in <URLResolver <URLPattern list> (admin:admin) 'admin/'>
2019-05-20 13:41:49,933 [Thread-33:4184] [C:\Users\Administrator.SC-201903241453\AppData\Local\Programs\Python\Python36-32\lib\site-packages\django\template\base.py:_resolve_lookup:878] [DEBUG]- Exception while resolving variable 'name' in template 'unknown'.
Traceback (most recent call last):
  File "C:\Users\Administrator.SC-201903241453\AppData\Local\Programs\Python\Python36-32\lib\site-packages\django\core\handlers\exception.py", line 35, in inner
    response = get_response(request)
  File "C:\Users\Administrator.SC-201903241453\AppData\Local\Programs\Python\Python36-32\lib\site-packages\django\core\handlers\base.py", line 113, in _get_response
    resolver_match = resolver.resolve(request.path_info)
  File "C:\Users\Administrator.SC-201903241453\AppData\Local\Programs\Python\Python36-32\lib\site-packages\django\urls\resolvers.py", line 523, in resolve
    raise Resolver404({'tried': tried, 'path': new_path})
django.urls.exceptions.Resolver404: {'tried': [[<URLResolver <URLPattern list> (admin:admin) 'admin/'>], [<URLResolver <module 'backend.version_1_0' from 'D:\\360MoveData\\Users\\Administrator.SC-201903241453\\Desktop\\backend-7-3\\backend\\version_1_0.py'> (None:None) 'api/v1.0/'>, <URLResolver <module 'apis.urls' from 'D:\\360MoveData\\Users\\Administrator.SC-201903241453\\Desktop\\backend-7-3\\apis\\urls.py'> (None:None) 'service/'>, <URLPattern 'weather'>], [<URLResolver <module 'backend.version_1_0' from 'D:\\360MoveData\\Users\\Administrator.SC-201903241453\\Desktop\\backend-7-3\\backend\\version_1_0.py'> (None:None) 'api/v1.0/'>, <URLResolver <module 'apis.urls' from 'D:\\360MoveData\\Users\\Administrator.SC-201903241453\\Desktop\\backend-7-3\\apis\\urls.py'> (None:None) 'service/'>, <URLPattern 'menu/user'>], [<URLResolver <module 'backend.version_1_0' from 'D:\\360MoveData\\Users\\Administrator.SC-201903241453\\Desktop\\backend-7-3\\backend\\version_1_0.py'> (None:None) 'api/v1.0/'>, <URLResolver <module 'apis.urls' from 'D:\\360MoveData\\Users\\Administrator.SC-201903241453\\Desktop\\backend-7-3\\apis\\urls.py'> (None:None) 'service/'>, <URLPattern 'menu/list'>], [<URLResolver <module 'backend.version_1_0' from 'D:\\360MoveData\\Users\\Administrator.SC-201903241453\\Desktop\\backend-7-3\\backend\\version_1_0.py'> (None:None) 'api/v1.0/'>, <URLResolver <module 'apis.urls' from 'D:\\360MoveData\\Users\\Administrator.SC-201903241453\\Desktop\\backend-7-3\\apis\\urls.py'> (None:None) 'service/'>, <URLPattern 'image'>], [<URLResolver <module 'backend.version_1_0' from 'D:\\360MoveData\\Users\\Administrator.SC-201903241453\\Desktop\\backend-7-3\\backend\\version_1_0.py'> (None:None) 'api/v1.0/'>, <URLResolver <module 'apis.urls' from 'D:\\360MoveData\\Users\\Administrator.SC-201903241453\\Desktop\\backend-7-3\\apis\\urls.py'> (None:None) 'service/'>, <URLPattern 'image/list'>], [<URLResolver <module 'backend.version_1_0' from 'D:\\360MoveData\\Users\\Administrator.SC-201903241453\\Desktop\\backend-7-3\\backend\\version_1_0.py'> (None:None) 'api/v1.0/'>, <URLResolver <module 'apis.urls' from 'D:\\360MoveData\\Users\\Administrator.SC-201903241453\\Desktop\\backend-7-3\\apis\\urls.py'> (None:None) 'service/'>, <URLPattern 'constellation'>], [<URLResolver <module 'backend.version_1_0' from 'D:\\360MoveData\\Users\\Administrator.SC-201903241453\\Desktop\\backend-7-3\\backend\\version_1_0.py'> (None:None) 'api/v1.0/'>, <URLResolver <module 'apis.urls' from 'D:\\360MoveData\\Users\\Administrator.SC-201903241453\\Desktop\\backend-7-3\\apis\\urls.py'> (None:None) 'service/'>, <URLPattern 'joke'>], [<URLResolver <module 'backend.version_1_0' from 'D:\\360MoveData\\Users\\Administrator.SC-201903241453\\Desktop\\backend-7-3\\backend\\version_1_0.py'> (None:None) 'api/v1.0/'>, <URLResolver <module 'apis.urls' from 'D:\\360MoveData\\Users\\Administrator.SC-201903241453\\Desktop\\backend-7-3\\apis\\urls.py'> (None:None) 'service/'>, <URLPattern 'today'>], [<URLResolver <module 'backend.version_1_0' from 'D:\\360MoveData\\Users\\Administrator.SC-201903241453\\Desktop\\backend-7-3\\backend\\version_1_0.py'> (None:None) 'api/v1.0/'>, <URLResolver <module 'apis.urls' from 'D:\\360MoveData\\Users\\Administrator.SC-201903241453\\Desktop\\backend-7-3\\apis\\urls.py'> (None:None) 'service/'>, <URLPattern 'stock'>], [<URLResolver <module 'backend.version_1_0' from 'D:\\360MoveData\\Users\\Administrator.SC-201903241453\\Desktop\\backend-7-3\\backend\\version_1_0.py'> (None:None) 'api/v1.0/'>, <URLResolver <module 'authorization.urls' from 'D:\\360MoveData\\Users\\Administrator.SC-201903241453\\Desktop\\backend-7-3\\authorization\\urls.py'> (None:None) 'auth/'>]], 'path': 'api/v1.0/service/'}

During handling of the above exception, another exception occurred:

Traceback (most recent call last):
  File "C:\Users\Administrator.SC-201903241453\AppData\Local\Programs\Python\Python36-32\lib\site-packages\django\template\base.py", line 835, in _resolve_lookup
    current = current[bit]
TypeError: 'URLResolver' object is not subscriptable

During handling of the above exception, another exception occurred:

Traceback (most recent call last):
  File "C:\Users\Administrator.SC-201903241453\AppData\Local\Programs\Python\Python36-32\lib\site-packages\django\template\base.py", line 843, in _resolve_lookup
    current = getattr(current, bit)
AttributeError: 'URLResolver' object has no attribute 'name'

During handling of the above exception, another exception occurred:

Traceback (most recent call last):
  File "C:\Users\Administrator.SC-201903241453\AppData\Local\Programs\Python\Python36-32\lib\site-packages\django\template\base.py", line 849, in _resolve_lookup
    current = current[int(bit)]
ValueError: invalid literal for int() with base 10: 'name'

During handling of the above exception, another exception occurred:

Traceback (most recent call last):
  File "C:\Users\Administrator.SC-201903241453\AppData\Local\Programs\Python\Python36-32\lib\site-packages\django\template\base.py", line 856, in _resolve_lookup
    (bit, current))  # missing attribute
django.template.base.VariableDoesNotExist: Failed lookup for key [name] in <URLResolver <module 'authorization.urls' from 'D:\\360MoveData\\Users\\Administrator.SC-201903241453\\Desktop\\backend-7-3\\authorization\\urls.py'> (None:None) 'auth/'>
2019-05-20 13:41:49,968 [Thread-33:4184] [C:\Users\Administrator.SC-201903241453\AppData\Local\Programs\Python\Python36-32\lib\site-packages\django\core\handlers\base.py:get_response:93] [WARNING]- Not Found: /api/v1.0/service/
2019-05-20 13:41:49,971 [Thread-33:4184] [C:\Users\Administrator.SC-201903241453\AppData\Local\Programs\Python\Python36-32\lib\site-packages\django\core\servers\basehttp.py:log_message:124] [WARNING]- "GET /api/v1.0/service/ HTTP/1.1" 404 4118
2019-05-20 13:42:05,336 [Thread-34:1116] [C:\Users\Administrator.SC-201903241453\AppData\Local\Programs\Python\Python36-32\lib\site-packages\django\db\backends\utils.py:execute:111] [DEBUG]- (0.001) SELECT @@SQL_AUTO_IS_NULL; args=None
2019-05-20 13:42:05,340 [Thread-34:1116] [C:\Users\Administrator.SC-201903241453\AppData\Local\Programs\Python\Python36-32\lib\site-packages\django\db\backends\utils.py:execute:111] [DEBUG]- (0.001) SET SESSION TRANSACTION ISOLATION LEVEL READ COMMITTED; args=None
2019-05-20 13:42:05,343 [Thread-34:1116] [C:\Users\Administrator.SC-201903241453\AppData\Local\Programs\Python\Python36-32\lib\site-packages\django\db\backends\utils.py:execute:111] [DEBUG]- (0.000) SELECT VERSION(); args=None
2019-05-20 13:42:05,350 [Thread-34:1116] [C:\Users\Administrator.SC-201903241453\AppData\Local\Programs\Python\Python36-32\lib\site-packages\django\db\backends\utils.py:execute:111] [DEBUG]- (0.000) SET SESSION TRANSACTION ISOLATION LEVEL READ COMMITTED; args=None
2019-05-20 13:42:05,354 [Thread-34:1116] [C:\Users\Administrator.SC-201903241453\AppData\Local\Programs\Python\Python36-32\lib\site-packages\django\db\backends\utils.py:execute:111] [DEBUG]- (0.001) SELECT `django_session`.`session_key`, `django_session`.`session_data`, `django_session`.`expire_date` FROM `django_session` WHERE (`django_session`.`session_key` = '7m9ujkc2e2in3a9sedd9fv82zwrnzj0z' AND `django_session`.`expire_date` > '2019-05-20 05:42:05'); args=('7m9ujkc2e2in3a9sedd9fv82zwrnzj0z', '2019-05-20 05:42:05')
2019-05-20 13:42:05,361 [Thread-34:1116] [C:\Users\Administrator.SC-201903241453\AppData\Local\Programs\Python\Python36-32\lib\site-packages\django\db\backends\utils.py:execute:111] [DEBUG]- (0.001) SELECT `auth_user`.`id`, `auth_user`.`password`, `auth_user`.`last_login`, `auth_user`.`is_superuser`, `auth_user`.`username`, `auth_user`.`first_name`, `auth_user`.`last_name`, `auth_user`.`email`, `auth_user`.`is_staff`, `auth_user`.`is_active`, `auth_user`.`date_joined` FROM `auth_user` WHERE `auth_user`.`id` = 1; args=(1,)
2019-05-20 13:42:05,415 [Thread-34:1116] [C:\Users\Administrator.SC-201903241453\AppData\Local\Programs\Python\Python36-32\lib\site-packages\django\template\base.py:_resolve_lookup:878] [DEBUG]- Exception while resolving variable 'is_popup' in template 'admin/index.html'.
Traceback (most recent call last):
  File "C:\Users\Administrator.SC-201903241453\AppData\Local\Programs\Python\Python36-32\lib\site-packages\django\template\base.py", line 835, in _resolve_lookup
    current = current[bit]
  File "C:\Users\Administrator.SC-201903241453\AppData\Local\Programs\Python\Python36-32\lib\site-packages\django\template\context.py", line 83, in __getitem__
    raise KeyError(key)
KeyError: 'is_popup'

During handling of the above exception, another exception occurred:

Traceback (most recent call last):
  File "C:\Users\Administrator.SC-201903241453\AppData\Local\Programs\Python\Python36-32\lib\site-packages\django\template\base.py", line 841, in _resolve_lookup
    if isinstance(current, BaseContext) and getattr(type(current), bit):
AttributeError: type object 'RequestContext' has no attribute 'is_popup'

During handling of the above exception, another exception occurred:

Traceback (most recent call last):
  File "C:\Users\Administrator.SC-201903241453\AppData\Local\Programs\Python\Python36-32\lib\site-packages\django\template\base.py", line 849, in _resolve_lookup
    current = current[int(bit)]
ValueError: invalid literal for int() with base 10: 'is_popup'

During handling of the above exception, another exception occurred:

Traceback (most recent call last):
  File "C:\Users\Administrator.SC-201903241453\AppData\Local\Programs\Python\Python36-32\lib\site-packages\django\template\base.py", line 856, in _resolve_lookup
    (bit, current))  # missing attribute
django.template.base.VariableDoesNotExist: Failed lookup for key [is_popup] in [{'True': True, 'False': False, 'None': None}, {'csrf_token': <SimpleLazyObject: <function csrf.<locals>._get_val at 0x033BCC00>>, 'request': <WSGIRequest: GET '/admin/'>, 'user': <SimpleLazyObject: <User: super>>, 'perms': <django.contrib.auth.context_processors.PermWrapper object at 0x033C88D0>, 'messages': <django.contrib.messages.storage.fallback.FallbackStorage object at 0x033D7F90>, 'DEFAULT_MESSAGE_LEVELS': {'DEBUG': 10, 'INFO': 20, 'SUCCESS': 25, 'WARNING': 30, 'ERROR': 40}}, {}, {'site_title': 'Django site admin', 'site_header': 'Django administration', 'site_url': '/', 'has_permission': True, 'available_apps': [{'name': 'Apis', 'app_label': 'apis', 'app_url': '/admin/apis/', 'has_module_perms': True, 'models': [{'name': 'Apps', 'object_name': 'App', 'perms': {'add': True, 'change': True, 'delete': True}, 'admin_url': '/admin/apis/app/', 'add_url': '/admin/apis/app/add/'}]}, {'name': 'Authentication and Authorization', 'app_label': 'auth', 'app_url': '/admin/auth/', 'has_module_perms': True, 'models': [{'name': 'Groups', 'object_name': 'Group', 'perms': {'add': True, 'change': True, 'delete': True}, 'admin_url': '/admin/auth/group/', 'add_url': '/admin/auth/group/add/'}, {'name': 'Users', 'object_name': 'User', 'perms': {'add': True, 'change': True, 'delete': True}, 'admin_url': '/admin/auth/user/', 'add_url': '/admin/auth/user/add/'}]}, {'name': 'Authorization', 'app_label': 'authorization', 'app_url': '/admin/authorization/', 'has_module_perms': True, 'models': [{'name': 'Users', 'object_name': 'User', 'perms': {'add': True, 'change': True, 'delete': True}, 'admin_url': '/admin/authorization/user/', 'add_url': '/admin/authorization/user/add/'}]}], 'title': 'Site administration', 'app_list': [{'name': 'Apis', 'app_label': 'apis', 'app_url': '/admin/apis/', 'has_module_perms': True, 'models': [{'name': 'Apps', 'object_name': 'App', 'perms': {'add': True, 'change': True, 'delete': True}, 'admin_url': '/admin/apis/app/', 'add_url': '/admin/apis/app/add/'}]}, {'name': 'Authentication and Authorization', 'app_label': 'auth', 'app_url': '/admin/auth/', 'has_module_perms': True, 'models': [{'name': 'Groups', 'object_name': 'Group', 'perms': {'add': True, 'change': True, 'delete': True}, 'admin_url': '/admin/auth/group/', 'add_url': '/admin/auth/group/add/'}, {'name': 'Users', 'object_name': 'User', 'perms': {'add': True, 'change': True, 'delete': True}, 'admin_url': '/admin/auth/user/', 'add_url': '/admin/auth/user/add/'}]}, {'name': 'Authorization', 'app_label': 'authorization', 'app_url': '/admin/authorization/', 'has_module_perms': True, 'models': [{'name': 'Users', 'object_name': 'User', 'perms': {'add': True, 'change': True, 'delete': True}, 'admin_url': '/admin/authorization/user/', 'add_url': '/admin/authorization/user/add/'}]}], 'LANGUAGE_CODE': 'en-us', 'LANGUAGE_BIDI': False}]
2019-05-20 13:42:05,440 [Thread-34:1116] [C:\Users\Administrator.SC-201903241453\AppData\Local\Programs\Python\Python36-32\lib\site-packages\django\template\base.py:_resolve_lookup:878] [DEBUG]- Exception while resolving variable 'is_popup' in template 'admin/index.html'.
Traceback (most recent call last):
  File "C:\Users\Administrator.SC-201903241453\AppData\Local\Programs\Python\Python36-32\lib\site-packages\django\template\base.py", line 835, in _resolve_lookup
    current = current[bit]
  File "C:\Users\Administrator.SC-201903241453\AppData\Local\Programs\Python\Python36-32\lib\site-packages\django\template\context.py", line 83, in __getitem__
    raise KeyError(key)
KeyError: 'is_popup'

During handling of the above exception, another exception occurred:

Traceback (most recent call last):
  File "C:\Users\Administrator.SC-201903241453\AppData\Local\Programs\Python\Python36-32\lib\site-packages\django\template\base.py", line 841, in _resolve_lookup
    if isinstance(current, BaseContext) and getattr(type(current), bit):
AttributeError: type object 'RequestContext' has no attribute 'is_popup'

During handling of the above exception, another exception occurred:

Traceback (most recent call last):
  File "C:\Users\Administrator.SC-201903241453\AppData\Local\Programs\Python\Python36-32\lib\site-packages\django\template\base.py", line 849, in _resolve_lookup
    current = current[int(bit)]
ValueError: invalid literal for int() with base 10: 'is_popup'

During handling of the above exception, another exception occurred:

Traceback (most recent call last):
  File "C:\Users\Administrator.SC-201903241453\AppData\Local\Programs\Python\Python36-32\lib\site-packages\django\template\base.py", line 856, in _resolve_lookup
    (bit, current))  # missing attribute
django.template.base.VariableDoesNotExist: Failed lookup for key [is_popup] in [{'True': True, 'False': False, 'None': None}, {'csrf_token': <SimpleLazyObject: <function csrf.<locals>._get_val at 0x033BCC00>>, 'request': <WSGIRequest: GET '/admin/'>, 'user': <SimpleLazyObject: <User: super>>, 'perms': <django.contrib.auth.context_processors.PermWrapper object at 0x033C88D0>, 'messages': <django.contrib.messages.storage.fallback.FallbackStorage object at 0x033D7F90>, 'DEFAULT_MESSAGE_LEVELS': {'DEBUG': 10, 'INFO': 20, 'SUCCESS': 25, 'WARNING': 30, 'ERROR': 40}}, {}, {'site_title': 'Django site admin', 'site_header': 'Django administration', 'site_url': '/', 'has_permission': True, 'available_apps': [{'name': 'Apis', 'app_label': 'apis', 'app_url': '/admin/apis/', 'has_module_perms': True, 'models': [{'name': 'Apps', 'object_name': 'App', 'perms': {'add': True, 'change': True, 'delete': True}, 'admin_url': '/admin/apis/app/', 'add_url': '/admin/apis/app/add/'}]}, {'name': 'Authentication and Authorization', 'app_label': 'auth', 'app_url': '/admin/auth/', 'has_module_perms': True, 'models': [{'name': 'Groups', 'object_name': 'Group', 'perms': {'add': True, 'change': True, 'delete': True}, 'admin_url': '/admin/auth/group/', 'add_url': '/admin/auth/group/add/'}, {'name': 'Users', 'object_name': 'User', 'perms': {'add': True, 'change': True, 'delete': True}, 'admin_url': '/admin/auth/user/', 'add_url': '/admin/auth/user/add/'}]}, {'name': 'Authorization', 'app_label': 'authorization', 'app_url': '/admin/authorization/', 'has_module_perms': True, 'models': [{'name': 'Users', 'object_name': 'User', 'perms': {'add': True, 'change': True, 'delete': True}, 'admin_url': '/admin/authorization/user/', 'add_url': '/admin/authorization/user/add/'}]}], 'title': 'Site administration', 'app_list': [{'name': 'Apis', 'app_label': 'apis', 'app_url': '/admin/apis/', 'has_module_perms': True, 'models': [{'name': 'Apps', 'object_name': 'App', 'perms': {'add': True, 'change': True, 'delete': True}, 'admin_url': '/admin/apis/app/', 'add_url': '/admin/apis/app/add/'}]}, {'name': 'Authentication and Authorization', 'app_label': 'auth', 'app_url': '/admin/auth/', 'has_module_perms': True, 'models': [{'name': 'Groups', 'object_name': 'Group', 'perms': {'add': True, 'change': True, 'delete': True}, 'admin_url': '/admin/auth/group/', 'add_url': '/admin/auth/group/add/'}, {'name': 'Users', 'object_name': 'User', 'perms': {'add': True, 'change': True, 'delete': True}, 'admin_url': '/admin/auth/user/', 'add_url': '/admin/auth/user/add/'}]}, {'name': 'Authorization', 'app_label': 'authorization', 'app_url': '/admin/authorization/', 'has_module_perms': True, 'models': [{'name': 'Users', 'object_name': 'User', 'perms': {'add': True, 'change': True, 'delete': True}, 'admin_url': '/admin/authorization/user/', 'add_url': '/admin/authorization/user/add/'}]}], 'LANGUAGE_CODE': 'en-us', 'LANGUAGE_BIDI': False}]
2019-05-20 13:42:05,479 [Thread-34:1116] [C:\Users\Administrator.SC-201903241453\AppData\Local\Programs\Python\Python36-32\lib\site-packages\django\db\backends\utils.py:execute:111] [DEBUG]- (0.012) SELECT `django_admin_log`.`id`, `django_admin_log`.`action_time`, `django_admin_log`.`user_id`, `django_admin_log`.`content_type_id`, `django_admin_log`.`object_id`, `django_admin_log`.`object_repr`, `django_admin_log`.`action_flag`, `django_admin_log`.`change_message`, `auth_user`.`id`, `auth_user`.`password`, `auth_user`.`last_login`, `auth_user`.`is_superuser`, `auth_user`.`username`, `auth_user`.`first_name`, `auth_user`.`last_name`, `auth_user`.`email`, `auth_user`.`is_staff`, `auth_user`.`is_active`, `auth_user`.`date_joined`, `django_content_type`.`id`, `django_content_type`.`app_label`, `django_content_type`.`model` FROM `django_admin_log` INNER JOIN `auth_user` ON (`django_admin_log`.`user_id` = `auth_user`.`id`) LEFT OUTER JOIN `django_content_type` ON (`django_admin_log`.`content_type_id` = `django_content_type`.`id`) WHERE `django_admin_log`.`user_id` = 1 ORDER BY `django_admin_log`.`action_time` DESC LIMIT 10; args=(1,)
2019-05-20 13:42:05,487 [Thread-34:1116] [C:\Users\Administrator.SC-201903241453\AppData\Local\Programs\Python\Python36-32\lib\site-packages\django\core\servers\basehttp.py:log_message:124] [INFO]- "GET /admin/ HTTP/1.1" 200 4278
2019-05-20 13:42:06,921 [Thread-35:6296] [C:\Users\Administrator.SC-201903241453\AppData\Local\Programs\Python\Python36-32\lib\site-packages\django\db\backends\utils.py:execute:111] [DEBUG]- (0.000) SELECT @@SQL_AUTO_IS_NULL; args=None
2019-05-20 13:42:06,923 [Thread-35:6296] [C:\Users\Administrator.SC-201903241453\AppData\Local\Programs\Python\Python36-32\lib\site-packages\django\db\backends\utils.py:execute:111] [DEBUG]- (0.000) SET SESSION TRANSACTION ISOLATION LEVEL READ COMMITTED; args=None
2019-05-20 13:42:06,926 [Thread-35:6296] [C:\Users\Administrator.SC-201903241453\AppData\Local\Programs\Python\Python36-32\lib\site-packages\django\db\backends\utils.py:execute:111] [DEBUG]- (0.001) SELECT VERSION(); args=None
2019-05-20 13:42:06,933 [Thread-35:6296] [C:\Users\Administrator.SC-201903241453\AppData\Local\Programs\Python\Python36-32\lib\site-packages\django\db\backends\utils.py:execute:111] [DEBUG]- (0.001) SET SESSION TRANSACTION ISOLATION LEVEL READ COMMITTED; args=None
2019-05-20 13:42:06,939 [Thread-35:6296] [C:\Users\Administrator.SC-201903241453\AppData\Local\Programs\Python\Python36-32\lib\site-packages\django\db\backends\utils.py:execute:111] [DEBUG]- (0.001) SELECT `django_session`.`session_key`, `django_session`.`session_data`, `django_session`.`expire_date` FROM `django_session` WHERE (`django_session`.`session_key` = '7m9ujkc2e2in3a9sedd9fv82zwrnzj0z' AND `django_session`.`expire_date` > '2019-05-20 05:42:06'); args=('7m9ujkc2e2in3a9sedd9fv82zwrnzj0z', '2019-05-20 05:42:06')
2019-05-20 13:42:06,944 [Thread-35:6296] [C:\Users\Administrator.SC-201903241453\AppData\Local\Programs\Python\Python36-32\lib\site-packages\django\db\backends\utils.py:execute:111] [DEBUG]- (0.001) SELECT `auth_user`.`id`, `auth_user`.`password`, `auth_user`.`last_login`, `auth_user`.`is_superuser`, `auth_user`.`username`, `auth_user`.`first_name`, `auth_user`.`last_name`, `auth_user`.`email`, `auth_user`.`is_staff`, `auth_user`.`is_active`, `auth_user`.`date_joined` FROM `auth_user` WHERE `auth_user`.`id` = 1; args=(1,)
2019-05-20 13:42:06,952 [Thread-35:6296] [C:\Users\Administrator.SC-201903241453\AppData\Local\Programs\Python\Python36-32\lib\site-packages\django\db\backends\utils.py:execute:111] [DEBUG]- (0.003) None; args=()
2019-05-20 13:42:06,953 [Thread-35:6296] [C:\Users\Administrator.SC-201903241453\AppData\Local\Programs\Python\Python36-32\lib\site-packages\django\core\handlers\exception.py:handle_uncaught_exception:118] [ERROR]- Internal Server Error: /admin/apis/app/
Traceback (most recent call last):
  File "C:\Users\Administrator.SC-201903241453\AppData\Local\Programs\Python\Python36-32\lib\site-packages\django\db\backends\utils.py", line 85, in _execute
    return self.cursor.execute(sql, params)
  File "C:\Users\Administrator.SC-201903241453\AppData\Local\Programs\Python\Python36-32\lib\site-packages\django\db\backends\mysql\base.py", line 71, in execute
    return self.cursor.execute(query, args)
  File "C:\Users\Administrator.SC-201903241453\AppData\Local\Programs\Python\Python36-32\lib\site-packages\MySQLdb\cursors.py", line 206, in execute
    res = self._query(query)
  File "C:\Users\Administrator.SC-201903241453\AppData\Local\Programs\Python\Python36-32\lib\site-packages\MySQLdb\cursors.py", line 312, in _query
    db.query(q)
  File "C:\Users\Administrator.SC-201903241453\AppData\Local\Programs\Python\Python36-32\lib\site-packages\MySQLdb\connections.py", line 224, in query
    _mysql.connection.query(self, query)
MySQLdb._exceptions.ProgrammingError: (1146, "Table 'backend.apis_app' doesn't exist")

The above exception was the direct cause of the following exception:

Traceback (most recent call last):
  File "C:\Users\Administrator.SC-201903241453\AppData\Local\Programs\Python\Python36-32\lib\site-packages\django\core\handlers\exception.py", line 35, in inner
    response = get_response(request)
  File "C:\Users\Administrator.SC-201903241453\AppData\Local\Programs\Python\Python36-32\lib\site-packages\django\core\handlers\base.py", line 128, in _get_response
    response = self.process_exception_by_middleware(e, request)
  File "C:\Users\Administrator.SC-201903241453\AppData\Local\Programs\Python\Python36-32\lib\site-packages\django\core\handlers\base.py", line 126, in _get_response
    response = wrapped_callback(request, *callback_args, **callback_kwargs)
  File "C:\Users\Administrator.SC-201903241453\AppData\Local\Programs\Python\Python36-32\lib\site-packages\django\contrib\admin\options.py", line 574, in wrapper
    return self.admin_site.admin_view(view)(*args, **kwargs)
  File "C:\Users\Administrator.SC-201903241453\AppData\Local\Programs\Python\Python36-32\lib\site-packages\django\utils\decorators.py", line 142, in _wrapped_view
    response = view_func(request, *args, **kwargs)
  File "C:\Users\Administrator.SC-201903241453\AppData\Local\Programs\Python\Python36-32\lib\site-packages\django\views\decorators\cache.py", line 44, in _wrapped_view_func
    response = view_func(request, *args, **kwargs)
  File "C:\Users\Administrator.SC-201903241453\AppData\Local\Programs\Python\Python36-32\lib\site-packages\django\contrib\admin\sites.py", line 223, in inner
    return view(request, *args, **kwargs)
  File "C:\Users\Administrator.SC-201903241453\AppData\Local\Programs\Python\Python36-32\lib\site-packages\django\utils\decorators.py", line 62, in _wrapper
    return bound_func(*args, **kwargs)
  File "C:\Users\Administrator.SC-201903241453\AppData\Local\Programs\Python\Python36-32\lib\site-packages\django\utils\decorators.py", line 142, in _wrapped_view
    response = view_func(request, *args, **kwargs)
  File "C:\Users\Administrator.SC-201903241453\AppData\Local\Programs\Python\Python36-32\lib\site-packages\django\utils\decorators.py", line 58, in bound_func
    return func.__get__(self, type(self))(*args2, **kwargs2)
  File "C:\Users\Administrator.SC-201903241453\AppData\Local\Programs\Python\Python36-32\lib\site-packages\django\contrib\admin\options.py", line 1570, in changelist_view
    cl = self.get_changelist_instance(request)
  File "C:\Users\Administrator.SC-201903241453\AppData\Local\Programs\Python\Python36-32\lib\site-packages\django\contrib\admin\options.py", line 705, in get_changelist_instance
    self,
  File "C:\Users\Administrator.SC-201903241453\AppData\Local\Programs\Python\Python36-32\lib\site-packages\django\contrib\admin\views\main.py", line 76, in __init__
    self.get_results(request)
  File "C:\Users\Administrator.SC-201903241453\AppData\Local\Programs\Python\Python36-32\lib\site-packages\django\contrib\admin\views\main.py", line 174, in get_results
    result_count = paginator.count
  File "C:\Users\Administrator.SC-201903241453\AppData\Local\Programs\Python\Python36-32\lib\site-packages\django\utils\functional.py", line 36, in __get__
    res = instance.__dict__[self.name] = self.func(instance)
  File "C:\Users\Administrator.SC-201903241453\AppData\Local\Programs\Python\Python36-32\lib\site-packages\django\core\paginator.py", line 85, in count
    return self.object_list.count()
  File "C:\Users\Administrator.SC-201903241453\AppData\Local\Programs\Python\Python36-32\lib\site-packages\django\db\models\query.py", line 387, in count
    return self.query.get_count(using=self.db)
  File "C:\Users\Administrator.SC-201903241453\AppData\Local\Programs\Python\Python36-32\lib\site-packages\django\db\models\sql\query.py", line 491, in get_count
    number = obj.get_aggregation(using, ['__count'])['__count']
  File "C:\Users\Administrator.SC-201903241453\AppData\Local\Programs\Python\Python36-32\lib\site-packages\django\db\models\sql\query.py", line 476, in get_aggregation
    result = compiler.execute_sql(SINGLE)
  File "C:\Users\Administrator.SC-201903241453\AppData\Local\Programs\Python\Python36-32\lib\site-packages\django\db\models\sql\compiler.py", line 1063, in execute_sql
    cursor.execute(sql, params)
  File "C:\Users\Administrator.SC-201903241453\AppData\Local\Programs\Python\Python36-32\lib\site-packages\django\db\backends\utils.py", line 100, in execute
    return super().execute(sql, params)
  File "C:\Users\Administrator.SC-201903241453\AppData\Local\Programs\Python\Python36-32\lib\site-packages\django\db\backends\utils.py", line 68, in execute
    return self._execute_with_wrappers(sql, params, many=False, executor=self._execute)
  File "C:\Users\Administrator.SC-201903241453\AppData\Local\Programs\Python\Python36-32\lib\site-packages\django\db\backends\utils.py", line 77, in _execute_with_wrappers
    return executor(sql, params, many, context)
  File "C:\Users\Administrator.SC-201903241453\AppData\Local\Programs\Python\Python36-32\lib\site-packages\django\db\backends\utils.py", line 85, in _execute
    return self.cursor.execute(sql, params)
  File "C:\Users\Administrator.SC-201903241453\AppData\Local\Programs\Python\Python36-32\lib\site-packages\django\db\utils.py", line 89, in __exit__
    raise dj_exc_value.with_traceback(traceback) from exc_value
  File "C:\Users\Administrator.SC-201903241453\AppData\Local\Programs\Python\Python36-32\lib\site-packages\django\db\backends\utils.py", line 85, in _execute
    return self.cursor.execute(sql, params)
  File "C:\Users\Administrator.SC-201903241453\AppData\Local\Programs\Python\Python36-32\lib\site-packages\django\db\backends\mysql\base.py", line 71, in execute
    return self.cursor.execute(query, args)
  File "C:\Users\Administrator.SC-201903241453\AppData\Local\Programs\Python\Python36-32\lib\site-packages\MySQLdb\cursors.py", line 206, in execute
    res = self._query(query)
  File "C:\Users\Administrator.SC-201903241453\AppData\Local\Programs\Python\Python36-32\lib\site-packages\MySQLdb\cursors.py", line 312, in _query
    db.query(q)
  File "C:\Users\Administrator.SC-201903241453\AppData\Local\Programs\Python\Python36-32\lib\site-packages\MySQLdb\connections.py", line 224, in query
    _mysql.connection.query(self, query)
django.db.utils.ProgrammingError: (1146, "Table 'backend.apis_app' doesn't exist")
2019-05-20 13:42:07,036 [Thread-35:6296] [C:\Users\Administrator.SC-201903241453\AppData\Local\Programs\Python\Python36-32\lib\site-packages\django\db\backends\utils.py:execute:111] [DEBUG]- (0.001) None; args=()
2019-05-20 13:42:07,137 [Thread-35:6296] [C:\Users\Administrator.SC-201903241453\AppData\Local\Programs\Python\Python36-32\lib\site-packages\django\core\servers\basehttp.py:log_message:124] [ERROR]- "GET /admin/apis/app/ HTTP/1.1" 500 201441
2019-05-22 16:16:27,543 [Dummy-1:5008] [C:\Users\Administrator.SC-201903241453\AppData\Local\Programs\Python\Python36-32\lib\site-packages\django\db\backends\utils.py:execute:111] [DEBUG]- (0.000) SELECT @@SQL_AUTO_IS_NULL; args=None
2019-05-22 16:16:27,543 [Dummy-1:5008] [C:\Users\Administrator.SC-201903241453\AppData\Local\Programs\Python\Python36-32\lib\site-packages\django\db\backends\utils.py:execute:111] [DEBUG]- (0.000) SET SESSION TRANSACTION ISOLATION LEVEL READ COMMITTED; args=None
2019-05-22 16:16:27,543 [Dummy-1:5008] [C:\Users\Administrator.SC-201903241453\AppData\Local\Programs\Python\Python36-32\lib\site-packages\django\db\backends\utils.py:execute:111] [DEBUG]- (0.000) SELECT VERSION(); args=None
2019-05-22 16:16:28,415 [Dummy-1:5008] [C:\Users\Administrator.SC-201903241453\AppData\Local\Programs\Python\Python36-32\lib\site-packages\django\db\backends\utils.py:execute:111] [DEBUG]- (0.000) SET SESSION TRANSACTION ISOLATION LEVEL READ COMMITTED; args=None
2019-05-22 16:16:28,415 [Dummy-1:5008] [C:\Users\Administrator.SC-201903241453\AppData\Local\Programs\Python\Python36-32\lib\site-packages\django\db\backends\utils.py:execute:111] [DEBUG]- (0.000) SHOW FULL TABLES; args=None
2019-05-22 16:16:28,425 [Dummy-1:5008] [C:\Users\Administrator.SC-201903241453\AppData\Local\Programs\Python\Python36-32\lib\site-packages\django\db\backends\utils.py:execute:111] [DEBUG]- (0.000) SELECT `django_migrations`.`app`, `django_migrations`.`name` FROM `django_migrations`; args=()
2019-05-22 16:18:55,036 [Thread-2:904] [C:\Users\Administrator.SC-201903241453\AppData\Local\Programs\Python\Python36-32\lib\site-packages\django\db\backends\utils.py:execute:111] [DEBUG]- (0.002) SELECT @@SQL_AUTO_IS_NULL; args=None
2019-05-22 16:18:55,039 [Thread-2:904] [C:\Users\Administrator.SC-201903241453\AppData\Local\Programs\Python\Python36-32\lib\site-packages\django\db\backends\utils.py:execute:111] [DEBUG]- (0.001) SET SESSION TRANSACTION ISOLATION LEVEL READ COMMITTED; args=None
2019-05-22 16:18:55,052 [Thread-2:904] [C:\Users\Administrator.SC-201903241453\AppData\Local\Programs\Python\Python36-32\lib\site-packages\django\db\backends\utils.py:execute:111] [DEBUG]- (0.009) None; args=()
2019-05-22 16:18:55,053 [Thread-2:904] [C:\Users\Administrator.SC-201903241453\AppData\Local\Programs\Python\Python36-32\lib\site-packages\django\core\handlers\exception.py:handle_uncaught_exception:118] [ERROR]- Internal Server Error: /api/v1.0/service/menu/list
Traceback (most recent call last):
  File "C:\Users\Administrator.SC-201903241453\AppData\Local\Programs\Python\Python36-32\lib\site-packages\django\db\backends\utils.py", line 85, in _execute
    return self.cursor.execute(sql, params)
  File "C:\Users\Administrator.SC-201903241453\AppData\Local\Programs\Python\Python36-32\lib\site-packages\django\db\backends\mysql\base.py", line 71, in execute
    return self.cursor.execute(query, args)
  File "C:\Users\Administrator.SC-201903241453\AppData\Local\Programs\Python\Python36-32\lib\site-packages\MySQLdb\cursors.py", line 206, in execute
    res = self._query(query)
  File "C:\Users\Administrator.SC-201903241453\AppData\Local\Programs\Python\Python36-32\lib\site-packages\MySQLdb\cursors.py", line 312, in _query
    db.query(q)
  File "C:\Users\Administrator.SC-201903241453\AppData\Local\Programs\Python\Python36-32\lib\site-packages\MySQLdb\connections.py", line 224, in query
    _mysql.connection.query(self, query)
MySQLdb._exceptions.ProgrammingError: (1146, "Table 'backend.apis_app' doesn't exist")

The above exception was the direct cause of the following exception:

Traceback (most recent call last):
  File "C:\Users\Administrator.SC-201903241453\AppData\Local\Programs\Python\Python36-32\lib\site-packages\django\core\handlers\exception.py", line 35, in inner
    response = get_response(request)
  File "C:\Users\Administrator.SC-201903241453\AppData\Local\Programs\Python\Python36-32\lib\site-packages\django\core\handlers\base.py", line 128, in _get_response
    response = self.process_exception_by_middleware(e, request)
  File "C:\Users\Administrator.SC-201903241453\AppData\Local\Programs\Python\Python36-32\lib\site-packages\django\core\handlers\base.py", line 126, in _get_response
    response = wrapped_callback(request, *callback_args, **callback_kwargs)
  File "D:\360MoveData\Users\Administrator.SC-201903241453\Desktop\backend-7-3\apis\views\menu.py", line 37, in get_menu
    for app in query_set:
  File "C:\Users\Administrator.SC-201903241453\AppData\Local\Programs\Python\Python36-32\lib\site-packages\django\db\models\query.py", line 272, in __iter__
    self._fetch_all()
  File "C:\Users\Administrator.SC-201903241453\AppData\Local\Programs\Python\Python36-32\lib\site-packages\django\db\models\query.py", line 1179, in _fetch_all
    self._result_cache = list(self._iterable_class(self))
  File "C:\Users\Administrator.SC-201903241453\AppData\Local\Programs\Python\Python36-32\lib\site-packages\django\db\models\query.py", line 54, in __iter__
    results = compiler.execute_sql(chunked_fetch=self.chunked_fetch, chunk_size=self.chunk_size)
  File "C:\Users\Administrator.SC-201903241453\AppData\Local\Programs\Python\Python36-32\lib\site-packages\django\db\models\sql\compiler.py", line 1063, in execute_sql
    cursor.execute(sql, params)
  File "C:\Users\Administrator.SC-201903241453\AppData\Local\Programs\Python\Python36-32\lib\site-packages\django\db\backends\utils.py", line 100, in execute
    return super().execute(sql, params)
  File "C:\Users\Administrator.SC-201903241453\AppData\Local\Programs\Python\Python36-32\lib\site-packages\django\db\backends\utils.py", line 68, in execute
    return self._execute_with_wrappers(sql, params, many=False, executor=self._execute)
  File "C:\Users\Administrator.SC-201903241453\AppData\Local\Programs\Python\Python36-32\lib\site-packages\django\db\backends\utils.py", line 77, in _execute_with_wrappers
    return executor(sql, params, many, context)
  File "C:\Users\Administrator.SC-201903241453\AppData\Local\Programs\Python\Python36-32\lib\site-packages\django\db\backends\utils.py", line 85, in _execute
    return self.cursor.execute(sql, params)
  File "C:\Users\Administrator.SC-201903241453\AppData\Local\Programs\Python\Python36-32\lib\site-packages\django\db\utils.py", line 89, in __exit__
    raise dj_exc_value.with_traceback(traceback) from exc_value
  File "C:\Users\Administrator.SC-201903241453\AppData\Local\Programs\Python\Python36-32\lib\site-packages\django\db\backends\utils.py", line 85, in _execute
    return self.cursor.execute(sql, params)
  File "C:\Users\Administrator.SC-201903241453\AppData\Local\Programs\Python\Python36-32\lib\site-packages\django\db\backends\mysql\base.py", line 71, in execute
    return self.cursor.execute(query, args)
  File "C:\Users\Administrator.SC-201903241453\AppData\Local\Programs\Python\Python36-32\lib\site-packages\MySQLdb\cursors.py", line 206, in execute
    res = self._query(query)
  File "C:\Users\Administrator.SC-201903241453\AppData\Local\Programs\Python\Python36-32\lib\site-packages\MySQLdb\cursors.py", line 312, in _query
    db.query(q)
  File "C:\Users\Administrator.SC-201903241453\AppData\Local\Programs\Python\Python36-32\lib\site-packages\MySQLdb\connections.py", line 224, in query
    _mysql.connection.query(self, query)
django.db.utils.ProgrammingError: (1146, "Table 'backend.apis_app' doesn't exist")
2019-05-22 16:18:55,116 [Thread-2:904] [C:\Users\Administrator.SC-201903241453\AppData\Local\Programs\Python\Python36-32\lib\site-packages\django\db\backends\utils.py:execute:111] [DEBUG]- (0.003) None; args=()
2019-05-22 16:18:55,120 [Thread-2:904] [C:\Users\Administrator.SC-201903241453\AppData\Local\Programs\Python\Python36-32\lib\site-packages\django\db\backends\utils.py:execute:111] [DEBUG]- (0.002) None; args=()
2019-05-22 16:18:55,127 [Thread-2:904] [C:\Users\Administrator.SC-201903241453\AppData\Local\Programs\Python\Python36-32\lib\site-packages\django\db\backends\utils.py:execute:111] [DEBUG]- (0.002) None; args=()
2019-05-22 16:18:55,132 [Thread-2:904] [C:\Users\Administrator.SC-201903241453\AppData\Local\Programs\Python\Python36-32\lib\site-packages\django\db\backends\utils.py:execute:111] [DEBUG]- (0.002) None; args=()
2019-05-22 16:18:55,233 [Thread-2:904] [C:\Users\Administrator.SC-201903241453\AppData\Local\Programs\Python\Python36-32\lib\site-packages\django\core\servers\basehttp.py:log_message:124] [ERROR]- "GET /api/v1.0/service/menu/list HTTP/1.1" 500 147757
2019-05-22 16:31:05,278 [Dummy-1:7204] [C:\Users\Administrator.SC-201903241453\AppData\Local\Programs\Python\Python36-32\lib\site-packages\django\db\backends\utils.py:execute:111] [DEBUG]- (0.000) SELECT @@SQL_AUTO_IS_NULL; args=None
2019-05-22 16:31:05,278 [Dummy-1:7204] [C:\Users\Administrator.SC-201903241453\AppData\Local\Programs\Python\Python36-32\lib\site-packages\django\db\backends\utils.py:execute:111] [DEBUG]- (0.000) SET SESSION TRANSACTION ISOLATION LEVEL READ COMMITTED; args=None
2019-05-22 16:31:05,278 [Dummy-1:7204] [C:\Users\Administrator.SC-201903241453\AppData\Local\Programs\Python\Python36-32\lib\site-packages\django\db\backends\utils.py:execute:111] [DEBUG]- (0.000) SELECT VERSION(); args=None
2019-05-22 16:31:05,908 [Dummy-1:7204] [C:\Users\Administrator.SC-201903241453\AppData\Local\Programs\Python\Python36-32\lib\site-packages\django\db\backends\utils.py:execute:111] [DEBUG]- (0.000) SET SESSION TRANSACTION ISOLATION LEVEL READ COMMITTED; args=None
2019-05-22 16:31:05,928 [Dummy-1:7204] [C:\Users\Administrator.SC-201903241453\AppData\Local\Programs\Python\Python36-32\lib\site-packages\django\db\backends\utils.py:execute:111] [DEBUG]- (0.020) SHOW FULL TABLES; args=None
2019-05-22 16:31:05,928 [Dummy-1:7204] [C:\Users\Administrator.SC-201903241453\AppData\Local\Programs\Python\Python36-32\lib\site-packages\django\db\backends\utils.py:execute:111] [DEBUG]- (0.000) SELECT `django_migrations`.`app`, `django_migrations`.`name` FROM `django_migrations`; args=()
2019-05-22 16:31:23,864 [Thread-2:5196] [C:\Users\Administrator.SC-201903241453\AppData\Local\Programs\Python\Python36-32\lib\site-packages\django\db\backends\utils.py:execute:111] [DEBUG]- (0.000) SELECT @@SQL_AUTO_IS_NULL; args=None
2019-05-22 16:31:23,866 [Thread-2:5196] [C:\Users\Administrator.SC-201903241453\AppData\Local\Programs\Python\Python36-32\lib\site-packages\django\db\backends\utils.py:execute:111] [DEBUG]- (0.001) SET SESSION TRANSACTION ISOLATION LEVEL READ COMMITTED; args=None
2019-05-22 16:31:23,868 [Thread-2:5196] [C:\Users\Administrator.SC-201903241453\AppData\Local\Programs\Python\Python36-32\lib\site-packages\django\db\backends\utils.py:execute:111] [DEBUG]- (0.001) None; args=()
2019-05-22 16:31:23,869 [Thread-2:5196] [C:\Users\Administrator.SC-201903241453\AppData\Local\Programs\Python\Python36-32\lib\site-packages\django\core\handlers\exception.py:handle_uncaught_exception:118] [ERROR]- Internal Server Error: /api/v1.0/service/menu/list
Traceback (most recent call last):
  File "C:\Users\Administrator.SC-201903241453\AppData\Local\Programs\Python\Python36-32\lib\site-packages\django\db\backends\utils.py", line 85, in _execute
    return self.cursor.execute(sql, params)
  File "C:\Users\Administrator.SC-201903241453\AppData\Local\Programs\Python\Python36-32\lib\site-packages\django\db\backends\mysql\base.py", line 71, in execute
    return self.cursor.execute(query, args)
  File "C:\Users\Administrator.SC-201903241453\AppData\Local\Programs\Python\Python36-32\lib\site-packages\MySQLdb\cursors.py", line 206, in execute
    res = self._query(query)
  File "C:\Users\Administrator.SC-201903241453\AppData\Local\Programs\Python\Python36-32\lib\site-packages\MySQLdb\cursors.py", line 312, in _query
    db.query(q)
  File "C:\Users\Administrator.SC-201903241453\AppData\Local\Programs\Python\Python36-32\lib\site-packages\MySQLdb\connections.py", line 224, in query
    _mysql.connection.query(self, query)
MySQLdb._exceptions.ProgrammingError: (1146, "Table 'backend.apis_app' doesn't exist")

The above exception was the direct cause of the following exception:

Traceback (most recent call last):
  File "C:\Users\Administrator.SC-201903241453\AppData\Local\Programs\Python\Python36-32\lib\site-packages\django\core\handlers\exception.py", line 35, in inner
    response = get_response(request)
  File "C:\Users\Administrator.SC-201903241453\AppData\Local\Programs\Python\Python36-32\lib\site-packages\django\core\handlers\base.py", line 128, in _get_response
    response = self.process_exception_by_middleware(e, request)
  File "C:\Users\Administrator.SC-201903241453\AppData\Local\Programs\Python\Python36-32\lib\site-packages\django\core\handlers\base.py", line 126, in _get_response
    response = wrapped_callback(request, *callback_args, **callback_kwargs)
  File "D:\360MoveData\Users\Administrator.SC-201903241453\Desktop\backend-7-3\apis\views\menu.py", line 37, in get_menu
    for app in query_set:
  File "C:\Users\Administrator.SC-201903241453\AppData\Local\Programs\Python\Python36-32\lib\site-packages\django\db\models\query.py", line 272, in __iter__
    self._fetch_all()
  File "C:\Users\Administrator.SC-201903241453\AppData\Local\Programs\Python\Python36-32\lib\site-packages\django\db\models\query.py", line 1179, in _fetch_all
    self._result_cache = list(self._iterable_class(self))
  File "C:\Users\Administrator.SC-201903241453\AppData\Local\Programs\Python\Python36-32\lib\site-packages\django\db\models\query.py", line 54, in __iter__
    results = compiler.execute_sql(chunked_fetch=self.chunked_fetch, chunk_size=self.chunk_size)
  File "C:\Users\Administrator.SC-201903241453\AppData\Local\Programs\Python\Python36-32\lib\site-packages\django\db\models\sql\compiler.py", line 1063, in execute_sql
    cursor.execute(sql, params)
  File "C:\Users\Administrator.SC-201903241453\AppData\Local\Programs\Python\Python36-32\lib\site-packages\django\db\backends\utils.py", line 100, in execute
    return super().execute(sql, params)
  File "C:\Users\Administrator.SC-201903241453\AppData\Local\Programs\Python\Python36-32\lib\site-packages\django\db\backends\utils.py", line 68, in execute
    return self._execute_with_wrappers(sql, params, many=False, executor=self._execute)
  File "C:\Users\Administrator.SC-201903241453\AppData\Local\Programs\Python\Python36-32\lib\site-packages\django\db\backends\utils.py", line 77, in _execute_with_wrappers
    return executor(sql, params, many, context)
  File "C:\Users\Administrator.SC-201903241453\AppData\Local\Programs\Python\Python36-32\lib\site-packages\django\db\backends\utils.py", line 85, in _execute
    return self.cursor.execute(sql, params)
  File "C:\Users\Administrator.SC-201903241453\AppData\Local\Programs\Python\Python36-32\lib\site-packages\django\db\utils.py", line 89, in __exit__
    raise dj_exc_value.with_traceback(traceback) from exc_value
  File "C:\Users\Administrator.SC-201903241453\AppData\Local\Programs\Python\Python36-32\lib\site-packages\django\db\backends\utils.py", line 85, in _execute
    return self.cursor.execute(sql, params)
  File "C:\Users\Administrator.SC-201903241453\AppData\Local\Programs\Python\Python36-32\lib\site-packages\django\db\backends\mysql\base.py", line 71, in execute
    return self.cursor.execute(query, args)
  File "C:\Users\Administrator.SC-201903241453\AppData\Local\Programs\Python\Python36-32\lib\site-packages\MySQLdb\cursors.py", line 206, in execute
    res = self._query(query)
  File "C:\Users\Administrator.SC-201903241453\AppData\Local\Programs\Python\Python36-32\lib\site-packages\MySQLdb\cursors.py", line 312, in _query
    db.query(q)
  File "C:\Users\Administrator.SC-201903241453\AppData\Local\Programs\Python\Python36-32\lib\site-packages\MySQLdb\connections.py", line 224, in query
    _mysql.connection.query(self, query)
django.db.utils.ProgrammingError: (1146, "Table 'backend.apis_app' doesn't exist")
2019-05-22 16:31:23,939 [Thread-2:5196] [C:\Users\Administrator.SC-201903241453\AppData\Local\Programs\Python\Python36-32\lib\site-packages\django\db\backends\utils.py:execute:111] [DEBUG]- (0.002) None; args=()
2019-05-22 16:31:23,943 [Thread-2:5196] [C:\Users\Administrator.SC-201903241453\AppData\Local\Programs\Python\Python36-32\lib\site-packages\django\db\backends\utils.py:execute:111] [DEBUG]- (0.002) None; args=()
2019-05-22 16:31:23,946 [Thread-2:5196] [C:\Users\Administrator.SC-201903241453\AppData\Local\Programs\Python\Python36-32\lib\site-packages\django\db\backends\utils.py:execute:111] [DEBUG]- (0.001) None; args=()
2019-05-22 16:31:23,948 [Thread-2:5196] [C:\Users\Administrator.SC-201903241453\AppData\Local\Programs\Python\Python36-32\lib\site-packages\django\db\backends\utils.py:execute:111] [DEBUG]- (0.001) None; args=()
2019-05-22 16:31:24,204 [Thread-2:5196] [C:\Users\Administrator.SC-201903241453\AppData\Local\Programs\Python\Python36-32\lib\site-packages\django\core\servers\basehttp.py:log_message:124] [ERROR]- "GET /api/v1.0/service/menu/list HTTP/1.1" 500 147816
2019-05-22 17:00:31,274 [Thread-3:7468] [C:\Users\Administrator.SC-201903241453\AppData\Local\Programs\Python\Python36-32\lib\site-packages\django\template\base.py:_resolve_lookup:878] [DEBUG]- Exception while resolving variable 'name' in template 'unknown'.
Traceback (most recent call last):
  File "C:\Users\Administrator.SC-201903241453\AppData\Local\Programs\Python\Python36-32\lib\site-packages\django\core\handlers\exception.py", line 35, in inner
    response = get_response(request)
  File "C:\Users\Administrator.SC-201903241453\AppData\Local\Programs\Python\Python36-32\lib\site-packages\django\core\handlers\base.py", line 113, in _get_response
    resolver_match = resolver.resolve(request.path_info)
  File "C:\Users\Administrator.SC-201903241453\AppData\Local\Programs\Python\Python36-32\lib\site-packages\django\urls\resolvers.py", line 523, in resolve
    raise Resolver404({'tried': tried, 'path': new_path})
django.urls.exceptions.Resolver404: {'tried': [[<URLResolver <URLPattern list> (admin:admin) 'admin/'>], [<URLResolver <module 'backend.version_1_0' from 'D:\\360MoveData\\Users\\Administrator.SC-201903241453\\Desktop\\backend-7-3\\backend\\version_1_0.py'> (None:None) 'api/v1.0/'>]], 'path': 'favicon.ico'}

During handling of the above exception, another exception occurred:

Traceback (most recent call last):
  File "C:\Users\Administrator.SC-201903241453\AppData\Local\Programs\Python\Python36-32\lib\site-packages\django\template\base.py", line 835, in _resolve_lookup
    current = current[bit]
TypeError: 'URLResolver' object is not subscriptable

During handling of the above exception, another exception occurred:

Traceback (most recent call last):
  File "C:\Users\Administrator.SC-201903241453\AppData\Local\Programs\Python\Python36-32\lib\site-packages\django\template\base.py", line 843, in _resolve_lookup
    current = getattr(current, bit)
AttributeError: 'URLResolver' object has no attribute 'name'

During handling of the above exception, another exception occurred:

Traceback (most recent call last):
  File "C:\Users\Administrator.SC-201903241453\AppData\Local\Programs\Python\Python36-32\lib\site-packages\django\template\base.py", line 849, in _resolve_lookup
    current = current[int(bit)]
ValueError: invalid literal for int() with base 10: 'name'

During handling of the above exception, another exception occurred:

Traceback (most recent call last):
  File "C:\Users\Administrator.SC-201903241453\AppData\Local\Programs\Python\Python36-32\lib\site-packages\django\template\base.py", line 856, in _resolve_lookup
    (bit, current))  # missing attribute
django.template.base.VariableDoesNotExist: Failed lookup for key [name] in <URLResolver <URLPattern list> (admin:admin) 'admin/'>
2019-05-22 17:00:31,330 [Thread-3:7468] [C:\Users\Administrator.SC-201903241453\AppData\Local\Programs\Python\Python36-32\lib\site-packages\django\template\base.py:_resolve_lookup:878] [DEBUG]- Exception while resolving variable 'name' in template 'unknown'.
Traceback (most recent call last):
  File "C:\Users\Administrator.SC-201903241453\AppData\Local\Programs\Python\Python36-32\lib\site-packages\django\core\handlers\exception.py", line 35, in inner
    response = get_response(request)
  File "C:\Users\Administrator.SC-201903241453\AppData\Local\Programs\Python\Python36-32\lib\site-packages\django\core\handlers\base.py", line 113, in _get_response
    resolver_match = resolver.resolve(request.path_info)
  File "C:\Users\Administrator.SC-201903241453\AppData\Local\Programs\Python\Python36-32\lib\site-packages\django\urls\resolvers.py", line 523, in resolve
    raise Resolver404({'tried': tried, 'path': new_path})
django.urls.exceptions.Resolver404: {'tried': [[<URLResolver <URLPattern list> (admin:admin) 'admin/'>], [<URLResolver <module 'backend.version_1_0' from 'D:\\360MoveData\\Users\\Administrator.SC-201903241453\\Desktop\\backend-7-3\\backend\\version_1_0.py'> (None:None) 'api/v1.0/'>]], 'path': 'favicon.ico'}

During handling of the above exception, another exception occurred:

Traceback (most recent call last):
  File "C:\Users\Administrator.SC-201903241453\AppData\Local\Programs\Python\Python36-32\lib\site-packages\django\template\base.py", line 835, in _resolve_lookup
    current = current[bit]
TypeError: 'URLResolver' object is not subscriptable

During handling of the above exception, another exception occurred:

Traceback (most recent call last):
  File "C:\Users\Administrator.SC-201903241453\AppData\Local\Programs\Python\Python36-32\lib\site-packages\django\template\base.py", line 843, in _resolve_lookup
    current = getattr(current, bit)
AttributeError: 'URLResolver' object has no attribute 'name'

During handling of the above exception, another exception occurred:

Traceback (most recent call last):
  File "C:\Users\Administrator.SC-201903241453\AppData\Local\Programs\Python\Python36-32\lib\site-packages\django\template\base.py", line 849, in _resolve_lookup
    current = current[int(bit)]
ValueError: invalid literal for int() with base 10: 'name'

During handling of the above exception, another exception occurred:

Traceback (most recent call last):
  File "C:\Users\Administrator.SC-201903241453\AppData\Local\Programs\Python\Python36-32\lib\site-packages\django\template\base.py", line 856, in _resolve_lookup
    (bit, current))  # missing attribute
django.template.base.VariableDoesNotExist: Failed lookup for key [name] in <URLResolver <module 'backend.version_1_0' from 'D:\\360MoveData\\Users\\Administrator.SC-201903241453\\Desktop\\backend-7-3\\backend\\version_1_0.py'> (None:None) 'api/v1.0/'>
2019-05-22 17:00:31,351 [Thread-3:7468] [C:\Users\Administrator.SC-201903241453\AppData\Local\Programs\Python\Python36-32\lib\site-packages\django\core\handlers\base.py:get_response:93] [WARNING]- Not Found: /favicon.ico
2019-05-22 17:00:31,355 [Thread-3:7468] [C:\Users\Administrator.SC-201903241453\AppData\Local\Programs\Python\Python36-32\lib\site-packages\django\core\servers\basehttp.py:log_message:124] [WARNING]- "GET /favicon.ico HTTP/1.1" 404 2082
